Workbook

Sheet Balance 2018.12
A1: Language/ Sprache/ 言語/ Linguagem >>> | B1: English | C1: =MATCH(B1, H3:L3,0) -> 1
A3: E | B3: Measures | C3: =VLOOKUP(A3,[1]Sheet2!A:F,1+'[1]Balance 2021.12 '!C$1,FALSE) -> Amount in Group Crcy | H3: English | I3: Deutsch | J3: 日本語 | K3: Portugues | L3: 中文
A4: FS Item | B4: FS Item | C4: J10 | D4: J1R | E4: J20 | F4: J2R
A5: 111100 | B5: =VLOOKUP(A5,Sheet2!A:F,1+'Balance 2018.12'!C$1,FALSE) -> Cash on hand | C5: 17278224 | D5: 17278224 | E5: 24046108 | F5: 24046108
A6: 111200 | B6: =VLOOKUP(A6,Sheet2!A:F,1+'Balance 2018.12'!C$1,FALSE) -> Short-term deposits and other cash equivalents | C6: 8057775.2 | D6: 8057775.2 | E6: 11214008 | F6: 11214008
A7: 121100 | B7: =VLOOKUP(A7,Sheet2!A:F,1+'Balance 2018.12'!C$1,FALSE) -> Trade receivables, Gross | C7: 27016242 | D7: 27026921 | E7: 37598510 | F7: 37613371
A8: 121190 | B8: =VLOOKUP(A8,Sheet2!A:F,1+'Balance 2018.12'!C$1,FALSE) -> Trade receivables, Allowance | C8: -931550.74 | D8: -931550.74 | E8: -1296439.4 | F8: -1296439.4
A9: 121200 | B9: =VLOOKUP(A9,Sheet2!A:F,1+'Balance 2018.12'!C$1,FALSE) -> Receivables on disposal of PPE, Current, Gross | C9: 8519.82 | D9: 8519.82 | E9: 11857.03 | F9: 11857.03
A10: 121300 | B10: =VLOOKUP(A10,Sheet2!A:F,1+'Balance 2018.12'!C$1,FALSE) -> Receivables / disp. Intang.assets, Current, Gross | C10: 5679.88 | D10: 5679.88 | E10: 7904.69 | F10: 7904.69
A11: 121400 | B11: =VLOOKUP(A11,Sheet2!A:F,1+'Balance 2018.12'!C$1,FALSE) -> Receivables / disp. invest. subsid, Current, Gross | C11: 1324.84 | D11: 1324.84 | E11: 1843.78 | F11: 1843.78
A12: 121500 | B12: =VLOOKUP(A12,Sheet2!A:F,1+'Balance 2018.12'!C$1,FALSE) -> Receivables / disp. Inv. oth entities, Current, GV | C12: 3974.51 | D12: 3974.51 | E12: 5531.33 | F12: 5531.33
A13: 121600 | B13: =VLOOKUP(A13,Sheet2!A:F,1+'Balance 2018.12'!C$1,FALSE) -> Receivables /disp. Inv. oth assets, Current, Gross | C13: 2839.94 | D13: 2839.94 | E13: 3952.35 | F13: 3952.35
A14: 121700 | B14: =VLOOKUP(A14,Sheet2!A:F,1+'Balance 2018.12'!C$1,FALSE) -> Dividends receivable | C14: 1500 | D14: 1500 | E14: 2087.55 | F14: 2087.55
A15: 121800 | B15: =VLOOKUP(A15,Sheet2!A:F,1+'Balance 2018.12'!C$1,FALSE) -> Other receivables, Current, Gross | C15: 678279.37 | D15: 678279.37 | E15: 943961.54 | F15: 943961.54
A16: 121900 | B16: =VLOOKUP(A16,Sheet2!A:F,1+'Balance 2018.12'!C$1,FALSE) -> Accrued interests on receivables | C16: 48278.95 | D16: 48278.95 | E16: 67189.82 | F16: 67189.82
... A164: 799000 | B164: =VLOOKUP(A164,Sheet2!A:F,1+'Balance 2018.12'!C$1,FALSE) -> Net income/loss | C164: 22090605 | D164: 22092426 | E164: 32497223 | F164: 32499901
A165: 13100D | B165: =VLOOKUP(A165,Sheet2!A:F,1+'Balance 2018.12'!C$1,FALSE) -> Clearing Account - Gross Margin B/S | C165: 0 | D165: 0 | E165: 0 | F165: 0
A166: 21100D | B166: =VLOOKUP(A166,Sheet2!A:F,1+'Balance 2018.12'!C$1,FALSE) -> Clearing account - Receivables/payables, Current | C166: 0 | D166: 0 | E166: 0 | F166: 0
A167: 21110D | B167: =VLOOKUP(A167,Sheet2!A:F,1+'Balance 2018.12'!C$1,FALSE) -> Clearing account - Trade Rec/Pay, Current | C167: 0 | D167: 0 | E167: 0 | F167: 0
A168: 21170D | B168: =VLOOKUP(A168,Sheet2!A:F,1+'Balance 2018.12'!C$1,FALSE) -> Clearing - Dividends rec/pay, Current | C168: 0 | D168: 0 | E168: 0 | F168: 0
A169: 22100D | B169: =VLOOKUP(A169,Sheet2!A:F,1+'Balance 2018.12'!C$1,FALSE) -> Clearing account - Financial assets/liab, Current | C169: 0 | D169: 0 | E169: 0 | F169: 0
A170: 28100D | B170: =VLOOKUP(A170,Sheet2!A:F,1+'Balance 2018.12'!C$1,FALSE) -> Clearing account - Receiv./payables, Non-current | C170: 0 | D170: 0 | E170: 0 | F170: 0
A171: 41200D | B171: =VLOOKUP(A171,Sheet2!A:F,1+'Balance 2018.12'!C$1,FALSE) -> Clearing account - Gross margin | C171: 0 | D171: 0 | E171: 0 | F171: 0
A172: 58000D | B172: =VLOOKUP(A172,Sheet2!A:F,1+'Balance 2018.12'!C$1,FALSE) -> Clearing account - Other operating | C172: 0 | D172: 0 | E172: 0.01 | F172: 0.01
A173: 65400D | B173: =VLOOKUP(A173,Sheet2!A:F,1+'Balance 2018.12'!C$1,FALSE) -> Clearing account - financial result | C173: 0 | D173: 0 | E173: -0.01 | F173: -0.01

Sheet Balance sheet 2018.12
A1: Language/ Sprache/ 言語/ Linguagem >>> | B1: English | C1: =MATCH(B1, H3:L3,0) -> 1
B3: Measures | C3: Sign-Adjusted Amount in Group Crcy | H3: English | I3: Deutsch | J3: 日本語 | K3: Portugues | L3: 中文
A4: FS Item | C4: J10 | D4: J1R | E4: J20 | F4: J2R
A5: 111100 | B5: =VLOOKUP(A5,Sheet2!A:F,1+'Balance sheet 2018.12'!C$1,FALSE) -> Cash on hand | C5: 17278224 | D5: 17278224 | E5: 24046108 | F5: 24046108
A6: 111200 | B6: =VLOOKUP(A6,Sheet2!A:F,1+'Balance sheet 2018.12'!C$1,FALSE) -> Short-term deposits and other cash equivalents | C6: 8057775.2 | D6: 8057775.2 | E6: 11214008 | F6: 11214008
A7: Y1/BS/T11100 | B7: =VLOOKUP(A7,Sheet2!A:F,1+'Balance sheet 2018.12'!C$1,FALSE) -> Cash and cash equivalents | C7: 25335999 | D7: 25335999 | E7: 35260116 | F7: 35260116
A8: 121100 | B8: =VLOOKUP(A8,Sheet2!A:F,1+'Balance sheet 2018.12'!C$1,FALSE) -> Trade receivables, Gross | C8: 27016242 | D8: 27026921 | E8: 37598510 | F8: 37613371
A9: 121190 | B9: =VLOOKUP(A9,Sheet2!A:F,1+'Balance sheet 2018.12'!C$1,FALSE) -> Trade receivables, Allowance | C9: -931550.74 | D9: -931550.74 | E9: -1296439.4 | F9: -1296439.4
A10: 121200 | B10: =VLOOKUP(A10,Sheet2!A:F,1+'Balance sheet 2018.12'!C$1,FALSE) -> Receivables on disposal of PPE, Current, Gross | C10: 8519.82 | D10: 8519.82 | E10: 11857.03 | F10: 11857.03
A11: 121300 | B11: =VLOOKUP(A11,Sheet2!A:F,1+'Balance sheet 2018.12'!C$1,FALSE) -> Receivables / disp. Intang.assets, Current, Gross | C11: 5679.88 | D11: 5679.88 | E11: 7904.69 | F11: 7904.69
A12: 121400 | B12: =VLOOKUP(A12,Sheet2!A:F,1+'Balance sheet 2018.12'!C$1,FALSE) -> Receivables / disp. invest. subsid, Current, Gross | C12: 1324.84 | D12: 1324.84 | E12: 1843.78 | F12: 1843.78
A13: 121500 | B13: =VLOOKUP(A13,Sheet2!A:F,1+'Balance sheet 2018.12'!C$1,FALSE) -> Receivables / disp. Inv. oth entities, Current, GV | C13: 3974.51 | D13: 3974.51 | E13: 5531.33 | F13: 5531.33
A14: 121600 | B14: =VLOOKUP(A14,Sheet2!A:F,1+'Balance sheet 2018.12'!C$1,FALSE) -> Receivables /disp. Inv. oth assets, Current, Gross | C14: 2839.94 | D14: 2839.94 | E14: 3952.35 | F14: 3952.35
A15: 121700 | B15: =VLOOKUP(A15,Sheet2!A:F,1+'Balance sheet 2018.12'!C$1,FALSE) -> Dividends receivable | C15: 1500 | D15: 1500 | E15: 2087.55 | F15: 2087.55
A16: 121800 | B16: =VLOOKUP(A16,Sheet2!A:F,1+'Balance sheet 2018.12'!C$1,FALSE) -> Other receivables, Current, Gross | C16: 678279.37 | D16: 678279.37 | E16: 943961.54 | F16: 943961.54
A17: 121900 | B17: =VLOOKUP(A17,Sheet2!A:F,1+'Balance sheet 2018.12'!C$1,FALSE) -> Accrued interests on receivables | C17: 48278.95 | D17: 48278.95 | E17: 67189.82 | F17: 67189.82
A18: 121990 | B18: =VLOOKUP(A18,Sheet2!A:F,1+'Balance sheet 2018.12'!C$1,FALSE) -> Other receivables, Allow | C18: -19879.57 | D18: -19879.57 | E18: -27666.4 | F18: -27666.4
A19: Y1/BS/T12100 | B19: =VLOOKUP(A19,Sheet2!A:F,1+'Balance sheet 2018.12'!C$1,FALSE) -> Trade and other current receivables | C19: 26815209 | D19: 26825888 | E19: 37318732 | F19: 37333594
A20: 123100 | B20: =VLOOKUP(A20,Sheet2!A:F,1+'Balance sheet 2018.12'!C$1,FALSE) -> Prepaid expenses | C20: 49494.5 | D20: 49494.5 | E20: 68881.51 | F20: 68881.51
A21: Y1/BS/T12300 | B21: =VLOOKUP(A21,Sheet2!A:F,1+'Balance sheet 2018.12'!C$1,FALSE) -> Other current assets | C21: 49494.5 | D21: 49494.5 | E21: 68881.51 | F21: 68881.51
A22: 131100 | B22: =VLOOKUP(A22,Sheet2!A:F,1+'Balance sheet 2018.12'!C$1,FALSE) -> Raw materials | C22: 2194399.5 | D22: 2194399.5 | E22: 3053946.2 | F22: 3053946.2
A23: 131200 | B23: =VLOOKUP(A23,Sheet2!A:F,1+'Balance sheet 2018.12'!C$1,FALSE) -> Merchandise | C23: 2568881.8 | D23: 2568881.8 | E23: 3575113.2 | F23: 3575113.2
A24: 131300 | B24: =VLOOKUP(A24,Sheet2!A:F,1+'Balance sheet 2018.12'!C$1,FALSE) -> Production supplies | C24: 2271.96 | D24: 2271.96 | E24: 3161.88 | F24: 3161.88
A25: 131400 | B25: =VLOOKUP(A25,Sheet2!A:F,1+'Balance sheet 2018.12'!C$1,FALSE) -> Work in progress | C25: 674933.05 | D25: 674933.05 | E25: 939304.45 | F25: 939304.45
A26: 131500 | B26: =VLOOKUP(A26,Sheet2!A:F,1+'Balance sheet 2018.12'!C$1,FALSE) -> Finished goods | C26: 685751.33 | D26: 685751.33 | E26: 954360.24 | F26: 954360.24
A27: 131600 | B27: =VLOOKUP(A27,Sheet2!A:F,1+'Balance sheet 2018.12'!C$1,FALSE) -> Other inventories | C27: 1419.98 | D27: 1419.98 | E27: 1976.17 | F27: 1976.17
A28: 13100D | B28: =VLOOKUP(A28,Sheet2!A:F,1+'Balance sheet 2018.12'!C$1,FALSE) -> Clearing Account - Gross Margin B/S | C28: 0 | D28: 0 | E28: 0 | F28: 0
A29: Y1/BS/T13100 | B29: =VLOOKUP(A29,Sheet2!A:F,1+'Balance sheet 2018.12'!C$1,FALSE) -> Inventories | C29: 6127657.6 | D29: 6127657.6 | E29: 8527862.1 | F29: 8527862.1
A30: 141100 | B30: =VLOOKUP(A30,Sheet2!A:F,1+'Balance sheet 2018.12'!C$1,FALSE) -> Other financial assets at FVTOCI, Current | C30: 20515.85 | D30: 20515.85 | E30: 28551.91 | F30: 28551.91
A31: 141200 | B31: =VLOOKUP(A31,Sheet2!A:F,1+'Balance sheet 2018.12'!C$1,FALSE) -> Derivatives, Current | C31: 10456 | D31: 10456 | E31: 14551.61 | F31: 14551.61
A32: 141300 | B32: =VLOOKUP(A32,Sheet2!A:F,1+'Balance sheet 2018.12'!C$1,FALSE) -> Financial assets at FVPL, Current | C32: 5711.86 | D32: 5711.86 | E32: 7949.2 | F32: 7949.2
A33: 141400 | B33: =VLOOKUP(A33,Sheet2!A:F,1+'Balance sheet 2018.12'!C$1,FALSE) -> Loans and cash advances, Current, Gross | C33: 31239.32 | D33: 31239.32 | E33: 43475.77 | F33: 43475.77
A34: 141490 | B34: =VLOOKUP(A34,Sheet2!A:F,1+'Balance sheet 2018.12'!C$1,FALSE) -> Loans and cash advances, Current, Allowance | C34: -8519.81 | D34: -8519.81 | E34: -11857.03 | F34: -11857.03
A35: Y1/BS/T14100 | B35: =VLOOKUP(A35,Sheet2!A:F,1+'Balance sheet 2018.12'!C$1,FALSE) -> Other current financial assets | C35: 59403.22 | D35: 59403.22 | E35: 82671.46 | F35: 82671.46
A36: Y1/BS/TAC100 | B36: =VLOOKUP(A36,Sheet2!A:F,1+'Balance sheet 2018.12'!C$1,FALSE) -> Current assets oth.than incl.in disposal groups | C36: 58387764 | D36: 58398442 | E36: 81258263 | F36: 81273125
A37: 151100 | B37: =VLOOKUP(A37,Sheet2!A:F,1+'Balance sheet 2018.12'!C$1,FALSE) -> NC assets or disp. groups classified HFS | C37: 2000 | D37: 2000 | E37: 2783.4 | F37: 2783.4
A38: Y1/BS/TAC200 | B38: =VLOOKUP(A38,Sheet2!A:F,1+'Balance sheet 2018.12'!C$1,FALSE) -> NC assets or disp. groups classified HFS/HDO | C38: 2000 | D38: 2000 | E38: 2783.4 | F38: 2783.4
A39: Y1/BS/TAC000 | B39: =VLOOKUP(A39,Sheet2!A:F,1+'Balance sheet 2018.12'!C$1,FALSE) -> Current assets | C39: 58389764 | D39: 58400442 | E39: 81261046 | F39: 81275908
A40: 161100 | B40: =VLOOKUP(A40,Sheet2!A:F,1+'Balance sheet 2018.12'!C$1,FALSE) -> Lands and buildings | C40: 22252278 | D40: 22252278 | E40: 30968499 | F40: 30968499
A41: 161190 | B41: =VLOOKUP(A41,Sheet2!A:F,1+'Balance sheet 2018.12'!C$1,FALSE) -> Lands and buildings, Depreciation | C41: -7107184.5 | D41: -7107184.5 | E41: -9891070 | F41: -9891070
...

Sheet P&L 2018.12
A1: Language/ Sprache/ 言語/ Linguagem >>> | B1: English | C1: =MATCH(B1, H3:L3,0) -> 1
C3: Sign-Adjusted Amount in Group Crcy | D3: Sign-Adjusted Amount in Group Crcy | E3: Sign-Adjusted Amount in Group Crcy | F3: Sign-Adjusted Amount in Group Crcy | H3: English | I3: Deutsch | J3: 日本語 | K3: Portugues | L3: 中文
A4: FS Item | C4: J10 | D4: J1R | E4: J20 | F4: J2R
A5: 411100 | B5: =VLOOKUP(A5,Sheet2!A:F,1+'P&L 2018.12'!C$1,FALSE) -> Sale of goods | C5: 2.4917317e+08 | D5: 2.4917317e+08 | E5: 3.6643401e+08 | F5: 3.6643401e+08
A6: Y1/PL/T41100 | B6: =VLOOKUP(A6,Sheet2!A:F,1+'P&L 2018.12'!C$1,FALSE) -> Revenue | C6: 2.4917317e+08 | D6: 2.4917317e+08 | E6: 3.6643401e+08 | F6: 3.6643401e+08
A7: 412100 | B7: =VLOOKUP(A7,Sheet2!A:F,1+'P&L 2018.12'!C$1,FALSE) -> Changes in Inventory | C7: -10949723 | D7: -10949723 | E7: -16089373 | F7: -16089373
A8: 412200 | B8: =VLOOKUP(A8,Sheet2!A:F,1+'P&L 2018.12'!C$1,FALSE) -> Cost of purchased services and materials | C8: -83321046 | D8: -83321046 | E8: -1.2253191e+08 | F8: -1.2253191e+08
A9: 41200D | B9: =VLOOKUP(A9,Sheet2!A:F,1+'P&L 2018.12'!C$1,FALSE) -> Clearing account - Gross margin | C9: 0 | D9: 0 | E9: 0 | F9: 0
A10: Y1/PL/T41200 | B10: =VLOOKUP(A10,Sheet2!A:F,1+'P&L 2018.12'!C$1,FALSE) -> Changes in Inventory / COS | C10: -94270769 | D10: -94270769 | E10: -1.3862129e+08 | F10: -1.3862129e+08
A11: Y1/PL/T41000 | B11: =VLOOKUP(A11,Sheet2!A:F,1+'P&L 2018.12'!C$1,FALSE) -> Gross margin | C11: 1.549024e+08 | D11: 1.549024e+08 | E11: 2.2781272e+08 | F11: 2.2781272e+08
A12: 511000 | B12: =VLOOKUP(A12,Sheet2!A:F,1+'P&L 2018.12'!C$1,FALSE) -> Gains on the disposal of PPE | C12: 1744709.9 | D12: 1744709.9 | E12: 2565770 | F12: 2565770
A13: 511100 | B13: =VLOOKUP(A13,Sheet2!A:F,1+'P&L 2018.12'!C$1,FALSE) -> Gains on the disposal of investment property | C13: 19220955 | D13: 19220955 | E13: 28266332 | F13: 28266332
A14: 511200 | B14: =VLOOKUP(A14,Sheet2!A:F,1+'P&L 2018.12'!C$1,FALSE) -> Gains on the disposal of intangible assets | C14: 13654.06 | D14: 13654.06 | E14: 20079.65 | F14: 20079.65
A15: 511300 | B15: =VLOOKUP(A15,Sheet2!A:F,1+'P&L 2018.12'!C$1,FALSE) -> Gains on the disposal of other assets | C15: 10939.96 | D15: 10939.96 | E15: 16088.3 | F15: 16088.3
A16: 515000 | B16: =VLOOKUP(A16,Sheet2!A:F,1+'P&L 2018.12'!C$1,FALSE) -> Other income | C16: 183961.98 | D16: 183961.98 | E16: 270534.46 | F16: 270534.46
A17: Y1/PL/T51000 | B17: =VLOOKUP(A17,Sheet2!A:F,1+'P&L 2018.12'!C$1,FALSE) -> Other operating income | C17: 21174221 | D17: 21174221 | E17: 31138804 | F17: 31138804
A18: 571000 | B18: =VLOOKUP(A18,Sheet2!A:F,1+'P&L 2018.12'!C$1,FALSE) -> Amort./depr./ impair. on fixed assets | C18: -30000 | D18: -30000 | E18: -44118 | F18: -44118
A19: Y1/PL/T57000 | B19: =VLOOKUP(A19,Sheet2!A:F,1+'P&L 2018.12'!C$1,FALSE) -> Depreciation | C19: -30000 | D19: -30000 | E19: -44118 | F19: -44118
A20: 584000 | B20: =VLOOKUP(A20,Sheet2!A:F,1+'P&L 2018.12'!C$1,FALSE) -> Accruals | C20: -134732.64 | D20: -134732.64 | E20: -198137.76 | F20: -198137.76
A21: 585000 | B21: =VLOOKUP(A21,Sheet2!A:F,1+'P&L 2018.12'!C$1,FALSE) -> Other expenses | C21: -1.300568e+08 | D21: -1.300568e+08 | E21: -1.9126151e+08 | F21: -1.9126151e+08
A22: 58000D | B22: =VLOOKUP(A22,Sheet2!A:F,1+'P&L 2018.12'!C$1,FALSE) -> Clearing account - Other operating | C22: 0 | D22: 0 | E22: -0.01 | F22: -0.01
A23: Y1/PL/T58000 | B23: =VLOOKUP(A23,Sheet2!A:F,1+'P&L 2018.12'!C$1,FALSE) -> Other operating expenses | C23: -1.3019154e+08 | D23: -1.3019154e+08 | E23: -1.9145964e+08 | F23: -1.9145964e+08
A24: Y1/PL/TOI000 | B24: =VLOOKUP(A24,Sheet2!A:F,1+'P&L 2018.12'!C$1,FALSE) -> Operating income / loss | C24: 45855086 | D24: 45855086 | E24: 67447763 | F24: 67447763
A25: 601000 | B25: =VLOOKUP(A25,Sheet2!A:F,1+'P&L 2018.12'!C$1,FALSE) -> Interest income | C25: 898112.87 | D25: 898112.87 | E25: 1320764.6 | F25: 1320764.6
A26: 602000 | B26: =VLOOKUP(A26,Sheet2!A:F,1+'P&L 2018.12'!C$1,FALSE) -> Financial fair value gains or losses | C26: 19888.12 | D26: 19888.12 | E26: 29247.47 | F26: 29247.47
A27: 603000 | B27: =VLOOKUP(A27,Sheet2!A:F,1+'P&L 2018.12'!C$1,FALSE) -> Dividends | C27: 185713.42 | D27: 185713.42 | E27: 273110.59 | F27: 273110.59
A28: 604000 | B28: =VLOOKUP(A28,Sheet2!A:F,1+'P&L 2018.12'!C$1,FALSE) -> Other financial income | C28: 564307.44 | D28: 564307.44 | E28: 829870.37 | F28: 829870.37
A29: Y1/PL/T60100 | B29: =VLOOKUP(A29,Sheet2!A:F,1+'P&L 2018.12'!C$1,FALSE) -> Finance income | C29: 1668021.9 | D29: 1668021.9 | E29: 2452993 | F29: 2452993
A30: 651000 | B30: =VLOOKUP(A30,Sheet2!A:F,1+'P&L 2018.12'!C$1,FALSE) -> Allowances (reversals) for provisions on shares | C30: 0 | D30: 0 | E30: 0 | F30: 0
A31: 652000 | B31: =VLOOKUP(A31,Sheet2!A:F,1+'P&L 2018.12'!C$1,FALSE) -> Interest expenses | C31: -62705.42 | D31: -62705.42 | E31: -92214.57 | F31: -92214.57
A32: 653000 | B32: =VLOOKUP(A32,Sheet2!A:F,1+'P&L 2018.12'!C$1,FALSE) -> Other financial expenses | C32: -1557108.7 | D32: -1554507.7 | E32: -2289883.7 | F32: -2286058.7
A33: 65400D | B33: =VLOOKUP(A33,Sheet2!A:F,1+'P&L 2018.12'!C$1,FALSE) -> Clearing account - financial result | C33: 0 | D33: 0 | E33: 0.01 | F33: 0.01
A34: Y1/PL/T65100 | B34: =VLOOKUP(A34,Sheet2!A:F,1+'P&L 2018.12'!C$1,FALSE) -> Finance costs | C34: -1619814.1 | D34: -1617213.1 | E34: -2382098.3 | F34: -2378273.2
A35: Y1/PL/TFI000 | B35: =VLOOKUP(A35,Sheet2!A:F,1+'P&L 2018.12'!C$1,FALSE) -> Financial result | C35: 48207.71 | D35: 50808.73 | E35: 70894.75 | F35: 74719.81
A36: 711000 | B36: =VLOOKUP(A36,Sheet2!A:F,1+'P&L 2018.12'!C$1,FALSE) -> Share of profit - associates / JV at equity method | C36: 30070.04 | D36: 29550.04 | E36: 44221 | F36: 43456.29
A37: Y1/PL/T71000 | B37: =VLOOKUP(A37,Sheet2!A:F,1+'P&L 2018.12'!C$1,FALSE) -> Share of profit - associates / JV at equity method | C37: 30070.04 | D37: 29550.04 | E37: 44221 | F37: 43456.29
A38: Y1/PL/TBT000 | B38: =VLOOKUP(A38,Sheet2!A:F,1+'P&L 2018.12'!C$1,FALSE) -> Profit (loss) before tax | C38: 45933363 | D38: 45935444 | E38: 67562879 | F38: 67565940
A39: 721000 | B39: =VLOOKUP(A39,Sheet2!A:F,1+'P&L 2018.12'!C$1,FALSE) -> Income tax | C39: -11151789 | D39: -11151789 | E39: -16399818 | F39: -16399818
A40: 722000 | B40: =VLOOKUP(A40,Sheet2!A:F,1+'P&L 2018.12'!C$1,FALSE) -> Deferred tax | C40: 102532.87 | D40: 102532.87 | E40: 150784.85 | F40: 150784.85
A41: Y1/PL/T72000 | B41: =VLOOKUP(A41,Sheet2!A:F,1+'P&L 2018.12'!C$1,FALSE) -> Tax | C41: -11049256 | D41: -11049256 | E41: -16249033 | F41: -16249033
...

Sheet Sheet2
B1: I_TXTMI_EN | C1: I_TXTMI_DE | D1: I_TXTMI_JA | E1: I_TXTMI_PT | F1: I_TXTMI_ZH
A2: Financial Statement Item | B2: Medium Text for FS Items | C2: Medium Text for FS Items | D2: Medium Text for FS Items | E2: Medium Text for FS Items | F2: Medium Text for FS Items
A4: 321200 | B4: NCI - Revaluation surplus before tax | C4: Minderheit - Neubewertungsrücklage vor Steuern | D4: NCI - 税引き前再評価剰余金 | E4: Interesse minorit.- exced.reaval.antes imposto | F4: NCI - 税前重估盈余
A5: 321150 | B5: NCI - Net income | C5: Minderheit - Jahresüberschuss | D5: NCI - 当期利益 | E5: Interesse minoritário - lucro líquido do exercício | F5: NCI - 净收入
A6: 321100 | B6: NCI - Reserves and retained earnings | C6: Minderheit - Rücklagen und Gewinnrücklagen | D6: NCI - 準備金および剰余金 | E6: Interesse minorit.- reservas e lucs.líqs.acums. | F6: NCI - 准备金和留存收益
A7: 317000 | B7: Net income | C7: Jahresüberschuss | D7: 当期利益 | E7: Lucro líquido do exercício | F7: 净收入
A8: 316000 | B8: Retained earnings | C8: Gewinnrücklage | D8: 剰余金 | E8: Utilização de resultado | F8: 留存收益
A9: 315100 | B9: Share of OCI & other movements - EM (local) | C9: Anteil am so. Gsmterg. u. an so. Bew. - EM (lok.) | D9: OCI およびその他移動の持分 - EM (ローカル) | E9: Participação OCI & outros movimentos - EP (local) | F9: 其他综合收入&其他移动的份额 - EM（本地）
A10: 315000 | B10: Equity component of compound financial instruments | C10: Eigenkapitalkomp. von zusammengesetzten FinInstr. | D10: 複合金融商品の資本要素 | E10: Componente patrimônio líq.instrs.fins.compostos | F10: 复合金融工具的权益组件
A11: 314900 | B11: Income tax on foreign currency translation reserve | C11: Ertragsteuer auf Währungsumrechnungsrücklage | D11: 外貨換算準備金の所得税 | E11: Imposto renda reserva conversão moeda estrangeira | F11: 外币换算准备金的所得税
A12: 314800 | B12: Foreign currency translation reserve, before tax | C12: Währungsumrechnungsrücklage, vor Steuern | D12: 税引き前外貨換算準備金 | E12: Reserva conversão moeda estrangeira, antes imposto | F12: 外币换算准备金，税前
A13: 314700 | B13: Income tax on recyclable fair value reserve | C13: Ertragsteuer auf wiederverwendb. Zeitwertrücklage | D13: 再利用時価準備金の所得税 | E13: Imposto renda sobre reserva val.atual reutilizável | F13: 可回收公允价值准备金所得税
A14: Y1/BS/T16100 | B14: Property, plant and equipment | C14: Sachanlagen | D14: 有形固定資産 | E14: Bem material | F14: 物业、工厂和设备
A15: Y1/BS/T14100 | B15: Other current financial assets | C15: Sonstige kurzfristige finanzielle Vermögenswerte | D15: その他流動金融資産 | E15: Outros imobilizados financeiros a curto prazo | F15: 其他流动金融资产
A16: Y1/BS/T13100 | B16: Inventories | C16: Vorräte | D16: 棚卸資産 | E16: Estoques | F16: 库存
A17: Y1/BS/T12300 | B17: Other current assets | C17: Sonstiges Umlaufvermögen | D17: その他流動資産 | E17: Outro ativo circulante | F17: 其他流动资产
A18: Y1/BS/T12200 | B18: Current tax assets | C18: Kurzfristige Steueransprüche | D18: 流動税金資産 | E18: Ativos de imposto a curto prazo | F18: 流动税资产
A19: Y1/BS/T12100 | B19: Trade and other current receivables | C19: Forderungen aus LuL und andere kurzfristige Ford. | D19: 売上債権およびその他流動債権 | E19: Créditos comerciais e outros a curto prazo | F19: 贸易和其他流动应收账款
A20: Y1/BS/T11100 | B20: Cash and cash equivalents | C20: Zahlungsmittel und Zahlungsmitteläquivalente | D20: 現金および現金同等物 | E20: Recursos líquidos | F20: 现金和现金等价物
A21: 604000 | B21: Other financial income | C21: Sonstige Finanzerträge | D21: その他財務収益 | E21: Outro rendimento financeiro | F21: 其他金融收入
A22: 603000 | B22: Dividends | C22: Dividenden | D22: 配当金 | E22: Dividendos | F22: 股息
A23: 602000 | B23: Financial fair value gains or losses | C23: Finanzgewinn oder -verlust Zeitwert | D23: 財務時価損益 | E23: Ganhos ou perdas valor atual financeiro | F23: 金融公允价值损益
A24: 601000 | B24: Interest income | C24: Zinserträge | D24: 受取利息 | E24: Rendimento juros | F24: 利息收入
A25: 586000 | B25: Operating fair value losses | C25: Betriebsverlust Zeitwert | D25: 営業時価損失 | E25: Perdas valor atual operacional | F25: 营业公允价值损失
A26: 585000 | B26: Other expenses | C26: Sonstiger betrieblicher Aufwand | D26: その他の費用 | E26: Outras despesas | F26: 其他费用
A27: 584000 | B27: Accruals | C27: Rückstellungen | D27: 見越 | E27: Provisões | F27: 应计
A28: 583000 | B28: Bad debt allowances | C28: Wertberichtigungen auf Forderungen | D28: 貸倒引当金 | E28: Provs.créds.irrecup. | F28: 坏账补贴
A29: 582000 | B29: Loss on the sale of shares | C29: Verlust aus dem Verkauf von Anteilen | D29: 株式売却損 | E29: Perdas na venda de participações | F29: 股份卖出损失
A30: 581000 | B30: Losses on the disposal of PPE | C30: Verluste aus dem Abgang von Sachanlagen | D30: 有形固定資産処分損 | E30: Perdas na alienação de bens materiais | F30: PPE 处置损失
A31: 572000 | B31: Impairment of goodwill | C31: Wertminderung des Geschäfts- oder Firmenwerts | D31: 連結調整勘定の減損 | E31: Depreciação de aviamento | F31: 商誉减值
A32: 571000 | B32: Amort./depr./ impair. on fixed assets | C32: Abschreibung auf Sachanlagen | D32: 固定資産の償却/減価償却/減損 | E32: Amort./deprec.imobilizados | F32: 固定资产摊销/折旧/减值
... A38: 513000 | B38: Reduction in general bad debt allowance | C38: Verminderung der Pauschalwertberichtigungen | D38: 一般貸倒引当金の減額 | E38: Redução em provisão geral créditos irrecuperáveis | F38: 常规坏账准备扣减
A39: 58000D | B39: Clearing account - Other operating | C39: Verrechnungskonto - Sonstiges Betriebsergebnis | D39: 消込勘定 - その他営業 | E39: Conta de compensação - outro resultado operacional | F39: 清账科目 - 其他运营
A40: 512000 | B40: Gains on the sale of shares | C40: Erträge aus dem Verkauf von Anteilen | D40: 株式売却益 | E40: Ganhos da venda de participações | F40: 股份卖出收益
A41: 314600 | B41: Recyclable fair value reserve, before tax | C41: Wiederverwendbare Zeitwertrücklage, vor Steuern | D41: 税引き前再利用時価準備金 | E41: Reserva val.atual reutilizável, anterior a imposto | F41: 可回收公允价值准备金，税前
A42: 262100 | B42: Warranty provision, Non-current | C42: Garantierückstellung, langfristig | D42: 非流動保証引当金 | E42: Provisão de garantia, longo prazo | F42: 非流动担保准备金
A43: 261100 | B43: Provisions for employee benefits, Non-current | C43: Rückst. für Leistungen an Arbeitnehmer, langfr. | D43: 従業員給付の非流動引当金 | E43: Provisões para benefícios empregado, longo prazo | F43: 非流动员工福利准备金
A44: 251000 | B44: Liabilities included in disposal groups HFS | C44: Verbindl. in Veräußerungsgruppen zur Veräußerung | D44: 処分グループ HFS に含まれる負債 | E44: Obrigs.incls.grupos alien.previstos p/alienação | F44: 处置组 HFS 中包括的负债
A45: 27100D | B45: Clearing account - Financial assets/liab, N-Curr | C45: VerrechKto - Fin. Vermögenswerte/Verbind., langfr. | D45: 消込勘定 - 非流動金融資産/負債 | E45: Conta compensação - imobs./passivos fins., LPrazo | F45: 清算科目 - 非流动财务资产/负债
A46: 242600 | B46: Miscellaneous provisions, Current | C46: Sonstige Rückstellungen, kurzfristig | D46: その他流動引当金 | E46: Provisões neutras, curto prazo | F46: 流动杂项准备金
...
