Workbook

Sheet Balance 2022.02
A1: Language/ Sprache/ 言語/ Linguagem >>> | B1: English | C1: =MATCH(B1, H3:L3,0) -> 1
A3: E | B3: Measures | C3: =VLOOKUP(A3,[1]Sheet2!A:F,1+'[1]Balance 2021.12 '!C$1,FALSE) -> Amount in Group Crcy | H3: English | I3: Deutsch | J3: 日本語 | K3: Portugues | L3: 中文
A4: FS Item | B4: FS Item | C4: J10 | D4: J20
A5: 111100 | B5: =VLOOKUP(A5,Sheet2!A:F,1+'Balance 2022.02'!C$1,FALSE) -> Cash on hand | C5: 26304622 | D5: 37352584
A6: 111200 | B6: =VLOOKUP(A6,Sheet2!A:F,1+'Balance 2022.02'!C$1,FALSE) -> Short-term deposits and other cash equivalents | C6: 3455192.4 | D6: 4906374.8
A7: 121100 | B7: =VLOOKUP(A7,Sheet2!A:F,1+'Balance 2022.02'!C$1,FALSE) -> Trade receivables, Gross | C7: 34193807 | D7: 48555232
A8: 121190 | B8: =VLOOKUP(A8,Sheet2!A:F,1+'Balance 2022.02'!C$1,FALSE) -> Trade receivables, Allowance | C8: -873012.25 | D8: -1239678
A9: 121200 | B9: =VLOOKUP(A9,Sheet2!A:F,1+'Balance 2022.02'!C$1,FALSE) -> Receivables on disposal of PPE, Current, Gross | C9: 7504.22 | D9: 10656
A10: 121300 | B10: =VLOOKUP(A10,Sheet2!A:F,1+'Balance 2022.02'!C$1,FALSE) -> Receivables / disp. Intang.assets, Current, Gross | C10: 4352.11 | D10: 6180
A11: 121400 | B11: =VLOOKUP(A11,Sheet2!A:F,1+'Balance 2022.02'!C$1,FALSE) -> Receivables / disp. invest. subsid, Current, Gross | C11: 990.42 | D11: 1406.4
A12: 121500 | B12: =VLOOKUP(A12,Sheet2!A:F,1+'Balance 2022.02'!C$1,FALSE) -> Receivables / disp. Inv. oth entities, Current, GV | C12: 1995.21 | D12: 2833.2
A13: 121600 | B13: =VLOOKUP(A13,Sheet2!A:F,1+'Balance 2022.02'!C$1,FALSE) -> Receivables /disp. Inv. oth assets, Current, Gross | C13: 2761.69 | D13: 3921.6
A14: 121700 | B14: =VLOOKUP(A14,Sheet2!A:F,1+'Balance 2022.02'!C$1,FALSE) -> Dividends receivable | C14: 1800 | D14: 2556
A15: 121800 | B15: =VLOOKUP(A15,Sheet2!A:F,1+'Balance 2022.02'!C$1,FALSE) -> Other receivables, Current, Gross | C15: 1084412.1 | D15: 1539866.1
A16: 121900 | B16: =VLOOKUP(A16,Sheet2!A:F,1+'Balance 2022.02'!C$1,FALSE) -> Accrued interests on receivables | C16: 49681.69 | D16: 70548
... A161: 799000 | B161: =VLOOKUP(A161,Sheet2!A:F,1+'Balance 2022.02'!C$1,FALSE) -> Net income/loss | C161: 6703108 | D161: 9344487
A162: 13100D | B162: =VLOOKUP(A162,Sheet2!A:F,1+'Balance 2022.02'!C$1,FALSE) -> Clearing Account - Gross Margin B/S | C162: 0 | D162: 0
A163: 1721HC | B163: =VLOOKUP(A163,Sheet2!A:F,1+'Balance 2022.02'!C$1,FALSE) -> Elimination of investment, held cons unit | C163: -2198133 | D163: -3157915.1
A164: 1721OC | B164: =VLOOKUP(A164,Sheet2!A:F,1+'Balance 2022.02'!C$1,FALSE) -> Elimination of investment, owner cons unit | C164: 2198133 | D164: 3157915.1
A165: 21100D | B165: =VLOOKUP(A165,Sheet2!A:F,1+'Balance 2022.02'!C$1,FALSE) -> Clearing account - Receivables/payables, Current | C165: 0 | D165: 0
A166: 21110D | B166: =VLOOKUP(A166,Sheet2!A:F,1+'Balance 2022.02'!C$1,FALSE) -> Clearing account - Trade Rec/Pay, Current | C166: -0.16 | D166: -0.24
A167: 21170D | B167: =VLOOKUP(A167,Sheet2!A:F,1+'Balance 2022.02'!C$1,FALSE) -> Clearing - Dividends rec/pay, Current | C167: 0 | D167: 0
A168: 22100D | B168: =VLOOKUP(A168,Sheet2!A:F,1+'Balance 2022.02'!C$1,FALSE) -> Clearing account - Financial assets/liab, Current | C168: -0.06 | D168: -0.08
A169: 27100D | B169: =VLOOKUP(A169,Sheet2!A:F,1+'Balance 2022.02'!C$1,FALSE) -> Clearing account - Financial assets/liab, N-Curr | C169: 0.08 | D169: 0.12
A170: 28100D | B170: =VLOOKUP(A170,Sheet2!A:F,1+'Balance 2022.02'!C$1,FALSE) -> Clearing account - Receiv./payables, Non-current | C170: -0.01 | D170: -0.02
A171: 41200D | B171: =VLOOKUP(A171,Sheet2!A:F,1+'Balance 2022.02'!C$1,FALSE) -> Clearing account - Gross margin | C171: 0 | D171: 0
A172: 58000D | B172: =VLOOKUP(A172,Sheet2!A:F,1+'Balance 2022.02'!C$1,FALSE) -> Clearing account - Other operating | C172: 0.33 | D172: 0.83
A173: 65400D | B173: =VLOOKUP(A173,Sheet2!A:F,1+'Balance 2022.02'!C$1,FALSE) -> Clearing account - financial result | C173: 0.64 | D173: -0.4

Sheet Balance sheet 2022.02
A1: Language/ Sprache/ 言語/ Linguagem >>> | B1: English | C1: =MATCH(B1, H3:L3,0) -> 1
B3: Measures | C3: Sign-Adjusted Amount in Group Crcy | H3: English | I3: Deutsch | J3: 日本語 | K3: Portugues | L3: 中文
A4: FS Item | B4: Version | C4: J10 | D4: J20
A5: 111100 | B5: =VLOOKUP(A5,Sheet2!A:F,1+'Balance sheet 2022.02'!C$1,FALSE) -> Cash on hand | C5: 26304622 | D5: 37352584
A6: 111200 | B6: =VLOOKUP(A6,Sheet2!A:F,1+'Balance sheet 2022.02'!C$1,FALSE) -> Short-term deposits and other cash equivalents | C6: 3455192.4 | D6: 4906374.8
A7: Y1/BS/T11100 | B7: =VLOOKUP(A7,Sheet2!A:F,1+'Balance sheet 2022.02'!C$1,FALSE) -> Cash and cash equivalents | C7: 29759814 | D7: 42258959
A8: 121100 | B8: =VLOOKUP(A8,Sheet2!A:F,1+'Balance sheet 2022.02'!C$1,FALSE) -> Trade receivables, Gross | C8: 34193807 | D8: 48555232
A9: 121190 | B9: =VLOOKUP(A9,Sheet2!A:F,1+'Balance sheet 2022.02'!C$1,FALSE) -> Trade receivables, Allowance | C9: -873012.25 | D9: -1239678
A10: 121200 | B10: =VLOOKUP(A10,Sheet2!A:F,1+'Balance sheet 2022.02'!C$1,FALSE) -> Receivables on disposal of PPE, Current, Gross | C10: 7504.22 | D10: 10656
A11: 121300 | B11: =VLOOKUP(A11,Sheet2!A:F,1+'Balance sheet 2022.02'!C$1,FALSE) -> Receivables / disp. Intang.assets, Current, Gross | C11: 4352.11 | D11: 6180
A12: 121400 | B12: =VLOOKUP(A12,Sheet2!A:F,1+'Balance sheet 2022.02'!C$1,FALSE) -> Receivables / disp. invest. subsid, Current, Gross | C12: 990.42 | D12: 1406.4
A13: 121500 | B13: =VLOOKUP(A13,Sheet2!A:F,1+'Balance sheet 2022.02'!C$1,FALSE) -> Receivables / disp. Inv. oth entities, Current, GV | C13: 1995.21 | D13: 2833.2
A14: 121600 | B14: =VLOOKUP(A14,Sheet2!A:F,1+'Balance sheet 2022.02'!C$1,FALSE) -> Receivables /disp. Inv. oth assets, Current, Gross | C14: 2761.69 | D14: 3921.6
A15: 121700 | B15: =VLOOKUP(A15,Sheet2!A:F,1+'Balance sheet 2022.02'!C$1,FALSE) -> Dividends receivable | C15: 1800 | D15: 2556
A16: 121800 | B16: =VLOOKUP(A16,Sheet2!A:F,1+'Balance sheet 2022.02'!C$1,FALSE) -> Other receivables, Current, Gross | C16: 1084412.1 | D16: 1539866.1
A17: 121900 | B17: =VLOOKUP(A17,Sheet2!A:F,1+'Balance sheet 2022.02'!C$1,FALSE) -> Accrued interests on receivables | C17: 49681.69 | D17: 70548
A18: 121990 | B18: =VLOOKUP(A18,Sheet2!A:F,1+'Balance sheet 2022.02'!C$1,FALSE) -> Other receivables, Allow | C18: -19963.38 | D18: -28348
A19: Y1/BS/T12100 | B19: =VLOOKUP(A19,Sheet2!A:F,1+'Balance sheet 2022.02'!C$1,FALSE) -> Trade and other current receivables | C19: 34454328 | D19: 48925173
A20: 122100 | B20: =VLOOKUP(A20,Sheet2!A:F,1+'Balance sheet 2022.02'!C$1,FALSE) -> Income tax receivables | C20: 0 | D20: 0
A21: Y1/BS/T12200 | B21: =VLOOKUP(A21,Sheet2!A:F,1+'Balance sheet 2022.02'!C$1,FALSE) -> Current tax assets | C21: 0 | D21: 0
A22: 123100 | B22: =VLOOKUP(A22,Sheet2!A:F,1+'Balance sheet 2022.02'!C$1,FALSE) -> Prepaid expenses | C22: 63429.05 | D22: 90069.31
A23: Y1/BS/T12300 | B23: =VLOOKUP(A23,Sheet2!A:F,1+'Balance sheet 2022.02'!C$1,FALSE) -> Other current assets | C23: 63429.05 | D23: 90069.31
A24: 131100 | B24: =VLOOKUP(A24,Sheet2!A:F,1+'Balance sheet 2022.02'!C$1,FALSE) -> Raw materials | C24: 2989078.3 | D24: 4244493.8
A25: 131200 | B25: =VLOOKUP(A25,Sheet2!A:F,1+'Balance sheet 2022.02'!C$1,FALSE) -> Merchandise | C25: 3644655.3 | D25: 5175413.8
A26: 131300 | B26: =VLOOKUP(A26,Sheet2!A:F,1+'Balance sheet 2022.02'!C$1,FALSE) -> Production supplies | C26: 2912.11 | D26: 4135.2
A27: 131400 | B27: =VLOOKUP(A27,Sheet2!A:F,1+'Balance sheet 2022.02'!C$1,FALSE) -> Work in progress | C27: 901848.7 | D27: 1280625.9
A28: 131500 | B28: =VLOOKUP(A28,Sheet2!A:F,1+'Balance sheet 2022.02'!C$1,FALSE) -> Finished goods | C28: 920917.06 | D28: 1307703.1
A29: 131600 | B29: =VLOOKUP(A29,Sheet2!A:F,1+'Balance sheet 2022.02'!C$1,FALSE) -> Other inventories | C29: 1966.48 | D29: 2792.4
A30: 13100D | B30: =VLOOKUP(A30,Sheet2!A:F,1+'Balance sheet 2022.02'!C$1,FALSE) -> Clearing Account - Gross Margin B/S | C30: 0 | D30: 0
A31: Y1/BS/T13100 | B31: =VLOOKUP(A31,Sheet2!A:F,1+'Balance sheet 2022.02'!C$1,FALSE) -> Inventories | C31: 8461377.9 | D31: 12015164
A32: 141100 | B32: =VLOOKUP(A32,Sheet2!A:F,1+'Balance sheet 2022.02'!C$1,FALSE) -> Other financial assets at FVTOCI, Current | C32: 18100 | D32: 25702
A33: 141200 | B33: =VLOOKUP(A33,Sheet2!A:F,1+'Balance sheet 2022.02'!C$1,FALSE) -> Derivatives, Current | C33: 4908 | D33: 6969.36
A34: 141300 | B34: =VLOOKUP(A34,Sheet2!A:F,1+'Balance sheet 2022.02'!C$1,FALSE) -> Financial assets at FVPL, Current | C34: 5840 | D34: 8292.8
A35: 141400 | B35: =VLOOKUP(A35,Sheet2!A:F,1+'Balance sheet 2022.02'!C$1,FALSE) -> Loans and cash advances, Current, Gross | C35: 39576.82 | D35: 56199.08
A36: 141490 | B36: =VLOOKUP(A36,Sheet2!A:F,1+'Balance sheet 2022.02'!C$1,FALSE) -> Loans and cash advances, Current, Allowance | C36: -9456.34 | D36: -13428
A37: Y1/BS/T14100 | B37: =VLOOKUP(A37,Sheet2!A:F,1+'Balance sheet 2022.02'!C$1,FALSE) -> Other current financial assets | C37: 58968.48 | D37: 83735.24
A38: Y1/BS/TAC100 | B38: =VLOOKUP(A38,Sheet2!A:F,1+'Balance sheet 2022.02'!C$1,FALSE) -> Current assets oth.than incl.in disposal groups | C38: 72797918 | D38: 1.033731e+08
A39: 151100 | B39: =VLOOKUP(A39,Sheet2!A:F,1+'Balance sheet 2022.02'!C$1,FALSE) -> NC assets or disp. groups classified HFS | C39: 2000 | D39: 2840
A40: Y1/BS/TAC200 | B40: =VLOOKUP(A40,Sheet2!A:F,1+'Balance sheet 2022.02'!C$1,FALSE) -> NC assets or disp. groups classified HFS/HDO | C40: 2000 | D40: 2840
A41: Y1/BS/TAC000 | B41: =VLOOKUP(A41,Sheet2!A:F,1+'Balance sheet 2022.02'!C$1,FALSE) -> Current assets | C41: 72799918 | D41: 1.0337594e+08
...

Sheet P&L 2022.02
A1: Language/ Sprache/ 言語/ Linguagem >>> | B1: English | C1: =MATCH(B1, H3:L3,0) -> 1
B3: Measures | C3: Sign-Adjusted Amount in Group Crcy | H3: English | I3: Deutsch | J3: 日本語 | K3: Portugues | L3: 中文
A4: FS Item | B4: FS Item | C4: J10 | D4: J20
A5: 411100 | B5: =VLOOKUP(A5,Sheet2!A:F,1+'P&L 2022.02'!C$1,FALSE) -> Sale of goods | C5: 3.6538595e+08 | D5: 5.1077408e+08
A6: Y1/PL/T41100 | B6: =VLOOKUP(A6,Sheet2!A:F,1+'P&L 2022.02'!C$1,FALSE) -> Revenue | C6: 3.6538595e+08 | D6: 5.1077408e+08
A7: 412100 | B7: =VLOOKUP(A7,Sheet2!A:F,1+'P&L 2022.02'!C$1,FALSE) -> Changes in Inventory | C7: -18046815 | D7: -25194846
A8: 412200 | B8: =VLOOKUP(A8,Sheet2!A:F,1+'P&L 2022.02'!C$1,FALSE) -> Cost of purchased services and materials | C8: -1.1437499e+08 | D8: -1.5992096e+08
A9: 41200D | B9: =VLOOKUP(A9,Sheet2!A:F,1+'P&L 2022.02'!C$1,FALSE) -> Clearing account - Gross margin | C9: 0 | D9: 0
A10: Y1/PL/T41200 | B10: =VLOOKUP(A10,Sheet2!A:F,1+'P&L 2022.02'!C$1,FALSE) -> Changes in Inventory / COS | C10: -1.324218e+08 | D10: -1.8511581e+08
A11: Y1/PL/T41000 | B11: =VLOOKUP(A11,Sheet2!A:F,1+'P&L 2022.02'!C$1,FALSE) -> Gross margin | C11: 2.3296415e+08 | D11: 3.2565827e+08
A12: 511000 | B12: =VLOOKUP(A12,Sheet2!A:F,1+'P&L 2022.02'!C$1,FALSE) -> Gains on the disposal of PPE | C12: 292362.21 | D12: 408133.48
A13: 511200 | B13: =VLOOKUP(A13,Sheet2!A:F,1+'P&L 2022.02'!C$1,FALSE) -> Gains on the disposal of intangible assets | C13: 653.49 | D13: 912.27
A14: 511300 | B14: =VLOOKUP(A14,Sheet2!A:F,1+'P&L 2022.02'!C$1,FALSE) -> Gains on the disposal of other assets | C14: 465.54 | D14: 648.97
A15: 512000 | B15: =VLOOKUP(A15,Sheet2!A:F,1+'P&L 2022.02'!C$1,FALSE) -> Gains on the sale of shares | C15: 347424 | D15: 468278.6
A16: 515000 | B16: =VLOOKUP(A16,Sheet2!A:F,1+'P&L 2022.02'!C$1,FALSE) -> Other income | C16: 42254.66 | D16: 58988.15
A17: Y1/PL/T51000 | B17: =VLOOKUP(A17,Sheet2!A:F,1+'P&L 2022.02'!C$1,FALSE) -> Other operating income | C17: 683159.9 | D17: 936961.47
A18: 585000 | B18: =VLOOKUP(A18,Sheet2!A:F,1+'P&L 2022.02'!C$1,FALSE) -> Other expenses | C18: -2.148743e+08 | D18: -3.0038157e+08
A19: 58000D | B19: =VLOOKUP(A19,Sheet2!A:F,1+'P&L 2022.02'!C$1,FALSE) -> Clearing account - Other operating | C19: -0.33 | D19: -0.83
A20: Y1/PL/T58000 | B20: =VLOOKUP(A20,Sheet2!A:F,1+'P&L 2022.02'!C$1,FALSE) -> Other operating expenses | C20: -2.148743e+08 | D20: -3.0038157e+08
A21: Y1/PL/TOI000 | B21: =VLOOKUP(A21,Sheet2!A:F,1+'P&L 2022.02'!C$1,FALSE) -> Operating income / loss | C21: 18773011 | D21: 26213656
A22: 601000 | B22: =VLOOKUP(A22,Sheet2!A:F,1+'P&L 2022.02'!C$1,FALSE) -> Interest income | C22: 281426.13 | D22: 392878.7
A23: 602000 | B23: =VLOOKUP(A23,Sheet2!A:F,1+'P&L 2022.02'!C$1,FALSE) -> Financial fair value gains or losses | C23: 5636.45 | D23: 7868.63
A24: 603000 | B24: =VLOOKUP(A24,Sheet2!A:F,1+'P&L 2022.02'!C$1,FALSE) -> Dividends | C24: 578749 | D24: 806370.98
A25: 604000 | B25: =VLOOKUP(A25,Sheet2!A:F,1+'P&L 2022.02'!C$1,FALSE) -> Other financial income | C25: 146403.13 | D25: 204380.19
A26: Y1/PL/T60100 | B26: =VLOOKUP(A26,Sheet2!A:F,1+'P&L 2022.02'!C$1,FALSE) -> Finance income | C26: 1012214.7 | D26: 1411498.5
A27: 652000 | B27: =VLOOKUP(A27,Sheet2!A:F,1+'P&L 2022.02'!C$1,FALSE) -> Interest expenses | C27: -26702 | D27: -37277.58
A28: 653000 | B28: =VLOOKUP(A28,Sheet2!A:F,1+'P&L 2022.02'!C$1,FALSE) -> Other financial expenses | C28: -1809727.3 | D28: -2529646
A29: 65400D | B29: =VLOOKUP(A29,Sheet2!A:F,1+'P&L 2022.02'!C$1,FALSE) -> Clearing account - financial result | C29: -0.64 | D29: 0.4
A30: Y1/PL/T65100 | B30: =VLOOKUP(A30,Sheet2!A:F,1+'P&L 2022.02'!C$1,FALSE) -> Finance costs | C30: -1836429.9 | D30: -2566923.1
A31: Y1/PL/TFI000 | B31: =VLOOKUP(A31,Sheet2!A:F,1+'P&L 2022.02'!C$1,FALSE) -> Financial result | C31: -824215.24 | D31: -1155424.6
A32: 711000 | B32: =VLOOKUP(A32,Sheet2!A:F,1+'P&L 2022.02'!C$1,FALSE) -> Share of profit - associates / JV at equity method | C32: 10400 | D32: 14512.03
A33: Y1/PL/T71000 | B33: =VLOOKUP(A33,Sheet2!A:F,1+'P&L 2022.02'!C$1,FALSE) -> Share of profit - associates / JV at equity method | C33: 10400 | D33: 14512.03
A34: Y1/PL/TBT000 | B34: =VLOOKUP(A34,Sheet2!A:F,1+'P&L 2022.02'!C$1,FALSE) -> Profit (loss) before tax | C34: 17959196 | D34: 25072744
A35: 721000 | B35: =VLOOKUP(A35,Sheet2!A:F,1+'P&L 2022.02'!C$1,FALSE) -> Income tax | C35: -9894489.5 | D35: -13826887
A36: 722000 | B36: =VLOOKUP(A36,Sheet2!A:F,1+'P&L 2022.02'!C$1,FALSE) -> Deferred tax | C36: 126105.31 | D36: 176052.59
A37: Y1/PL/T72000 | B37: =VLOOKUP(A37,Sheet2!A:F,1+'P&L 2022.02'!C$1,FALSE) -> Tax | C37: -9768384.2 | D37: -13650835
A38: Y1/PL/TCO100 | B38: =VLOOKUP(A38,Sheet2!A:F,1+'P&L 2022.02'!C$1,FALSE) -> Profit (loss) from continuing operations | C38: 8190811.4 | D38: 11421909
A39: 730000 | B39: =VLOOKUP(A39,Sheet2!A:F,1+'P&L 2022.02'!C$1,FALSE) -> Profit (loss) from discontinued operations | C39: -180992.28 | D39: -252678.13
A40: Y1/PL/T73000 | B40: =VLOOKUP(A40,Sheet2!A:F,1+'P&L 2022.02'!C$1,FALSE) -> Profit (loss) from discontinued operations | C40: -180992.28 | D40: -252678.13
A41: 792000 | B41: =VLOOKUP(A41,Sheet2!A:F,1+'P&L 2022.02'!C$1,FALSE) -> Net income - NCI | C41: -1306711.1 | D41: -1824743.9
...

Sheet Sheet2
B1: I_TXTMI_EN | C1: I_TXTMI_DE | D1: I_TXTMI_JA | E1: I_TXTMI_PT | F1: I_TXTMI_ZH
A2: Financial Statement Item | B2: Medium Text for FS Items | C2: Medium Text for FS Items | D2: Medium Text for FS Items | E2: Medium Text for FS Items | F2: Medium Text for FS Items
A4: 321200 | B4: NCI - Revaluation surplus before tax | C4: Minderheit - Neubewertungsrücklage vor Steuern | D4: NCI - 税引き前再評価剰余金 | E4: Interesse minorit.- exced.reaval.antes imposto | F4: NCI - 税前重估盈余
A5: 321150 | B5: NCI - Net income | C5: Minderheit - Jahresüberschuss | D5: NCI - 当期利益 | E5: Interesse minoritário - lucro líquido do exercício | F5: NCI - 净收入
A6: 321100 | B6: NCI - Reserves and retained earnings | C6: Minderheit - Rücklagen und Gewinnrücklagen | D6: NCI - 準備金および剰余金 | E6: Interesse minorit.- reservas e lucs.líqs.acums. | F6: NCI - 准备金和留存收益
A7: 317000 | B7: Net income | C7: Jahresüberschuss | D7: 当期利益 | E7: Lucro líquido do exercício | F7: 净收入
A8: 316000 | B8: Retained earnings | C8: Gewinnrücklage | D8: 剰余金 | E8: Utilização de resultado | F8: 留存收益
A9: 315100 | B9: Share of OCI & other movements - EM (local) | C9: Anteil am so. Gsmterg. u. an so. Bew. - EM (lok.) | D9: OCI およびその他移動の持分 - EM (ローカル) | E9: Participação OCI & outros movimentos - EP (local) | F9: 其他综合收入&其他移动的份额 - EM（本地）
A10: 315000 | B10: Equity component of compound financial instruments | C10: Eigenkapitalkomp. von zusammengesetzten FinInstr. | D10: 複合金融商品の資本要素 | E10: Componente patrimônio líq.instrs.fins.compostos | F10: 复合金融工具的权益组件
A11: 314900 | B11: Income tax on foreign currency translation reserve | C11: Ertragsteuer auf Währungsumrechnungsrücklage | D11: 外貨換算準備金の所得税 | E11: Imposto renda reserva conversão moeda estrangeira | F11: 外币换算准备金的所得税
A12: 314800 | B12: Foreign currency translation reserve, before tax | C12: Währungsumrechnungsrücklage, vor Steuern | D12: 税引き前外貨換算準備金 | E12: Reserva conversão moeda estrangeira, antes imposto | F12: 外币换算准备金，税前
A13: 314700 | B13: Income tax on recyclable fair value reserve | C13: Ertragsteuer auf wiederverwendb. Zeitwertrücklage | D13: 再利用時価準備金の所得税 | E13: Imposto renda sobre reserva val.atual reutilizável | F13: 可回收公允价值准备金所得税
A14: Y1/BS/T16100 | B14: Property, plant and equipment | C14: Sachanlagen | D14: 有形固定資産 | E14: Bem material | F14: 物业、工厂和设备
A15: Y1/BS/T14100 | B15: Other current financial assets | C15: Sonstige kurzfristige finanzielle Vermögenswerte | D15: その他流動金融資産 | E15: Outros imobilizados financeiros a curto prazo | F15: 其他流动金融资产
A16: Y1/BS/T13100 | B16: Inventories | C16: Vorräte | D16: 棚卸資産 | E16: Estoques | F16: 库存
A17: Y1/BS/T12300 | B17: Other current assets | C17: Sonstiges Umlaufvermögen | D17: その他流動資産 | E17: Outro ativo circulante | F17: 其他流动资产
A18: Y1/BS/T12200 | B18: Current tax assets | C18: Kurzfristige Steueransprüche | D18: 流動税金資産 | E18: Ativos de imposto a curto prazo | F18: 流动税资产
A19: Y1/BS/T12100 | B19: Trade and other current receivables | C19: Forderungen aus LuL und andere kurzfristige Ford. | D19: 売上債権およびその他流動債権 | E19: Créditos comerciais e outros a curto prazo | F19: 贸易和其他流动应收账款
A20: Y1/BS/T11100 | B20: Cash and cash equivalents | C20: Zahlungsmittel und Zahlungsmitteläquivalente | D20: 現金および現金同等物 | E20: Recursos líquidos | F20: 现金和现金等价物
A21: 604000 | B21: Other financial income | C21: Sonstige Finanzerträge | D21: その他財務収益 | E21: Outro rendimento financeiro | F21: 其他金融收入
A22: 603000 | B22: Dividends | C22: Dividenden | D22: 配当金 | E22: Dividendos | F22: 股息
A23: 602000 | B23: Financial fair value gains or losses | C23: Finanzgewinn oder -verlust Zeitwert | D23: 財務時価損益 | E23: Ganhos ou perdas valor atual financeiro | F23: 金融公允价值损益
A24: 601000 | B24: Interest income | C24: Zinserträge | D24: 受取利息 | E24: Rendimento juros | F24: 利息收入
A25: 586000 | B25: Operating fair value losses | C25: Betriebsverlust Zeitwert | D25: 営業時価損失 | E25: Perdas valor atual operacional | F25: 营业公允价值损失
A26: 585000 | B26: Other expenses | C26: Sonstiger betrieblicher Aufwand | D26: その他の費用 | E26: Outras despesas | F26: 其他费用
A27: 584000 | B27: Accruals | C27: Rückstellungen | D27: 見越 | E27: Provisões | F27: 应计
A28: 583000 | B28: Bad debt allowances | C28: Wertberichtigungen auf Forderungen | D28: 貸倒引当金 | E28: Provs.créds.irrecup. | F28: 坏账补贴
A29: 582000 | B29: Loss on the sale of shares | C29: Verlust aus dem Verkauf von Anteilen | D29: 株式売却損 | E29: Perdas na venda de participações | F29: 股份卖出损失
A30: 581000 | B30: Losses on the disposal of PPE | C30: Verluste aus dem Abgang von Sachanlagen | D30: 有形固定資産処分損 | E30: Perdas na alienação de bens materiais | F30: PPE 处置损失
A31: 572000 | B31: Impairment of goodwill | C31: Wertminderung des Geschäfts- oder Firmenwerts | D31: 連結調整勘定の減損 | E31: Depreciação de aviamento | F31: 商誉减值
A32: 571000 | B32: Amort./depr./ impair. on fixed assets | C32: Abschreibung auf Sachanlagen | D32: 固定資産の償却/減価償却/減損 | E32: Amort./deprec.imobilizados | F32: 固定资产摊销/折旧/减值
... A38: 513000 | B38: Reduction in general bad debt allowance | C38: Verminderung der Pauschalwertberichtigungen | D38: 一般貸倒引当金の減額 | E38: Redução em provisão geral créditos irrecuperáveis | F38: 常规坏账准备扣减
A39: 58000D | B39: Clearing account - Other operating | C39: Verrechnungskonto - Sonstiges Betriebsergebnis | D39: 消込勘定 - その他営業 | E39: Conta de compensação - outro resultado operacional | F39: 清账科目 - 其他运营
A40: 512000 | B40: Gains on the sale of shares | C40: Erträge aus dem Verkauf von Anteilen | D40: 株式売却益 | E40: Ganhos da venda de participações | F40: 股份卖出收益
A41: 314600 | B41: Recyclable fair value reserve, before tax | C41: Wiederverwendbare Zeitwertrücklage, vor Steuern | D41: 税引き前再利用時価準備金 | E41: Reserva val.atual reutilizável, anterior a imposto | F41: 可回收公允价值准备金，税前
A42: 262100 | B42: Warranty provision, Non-current | C42: Garantierückstellung, langfristig | D42: 非流動保証引当金 | E42: Provisão de garantia, longo prazo | F42: 非流动担保准备金
A43: 261100 | B43: Provisions for employee benefits, Non-current | C43: Rückst. für Leistungen an Arbeitnehmer, langfr. | D43: 従業員給付の非流動引当金 | E43: Provisões para benefícios empregado, longo prazo | F43: 非流动员工福利准备金
A44: 251000 | B44: Liabilities included in disposal groups HFS | C44: Verbindl. in Veräußerungsgruppen zur Veräußerung | D44: 処分グループ HFS に含まれる負債 | E44: Obrigs.incls.grupos alien.previstos p/alienação | F44: 处置组 HFS 中包括的负债
A45: 27100D | B45: Clearing account - Financial assets/liab, N-Curr | C45: VerrechKto - Fin. Vermögenswerte/Verbind., langfr. | D45: 消込勘定 - 非流動金融資産/負債 | E45: Conta compensação - imobs./passivos fins., LPrazo | F45: 清算科目 - 非流动财务资产/负债
A46: 242600 | B46: Miscellaneous provisions, Current | C46: Sonstige Rückstellungen, kurzfristig | D46: その他流動引当金 | E46: Provisões neutras, curto prazo | F46: 流动杂项准备金
...
