Workbook

Sheet Balance 2023.12
A1: Language/ Sprache/ 言語/ Linguagem >>> | B1: English | C1: =MATCH(B1, H3:L3,0) -> 1
A3: E | B3: Measures | C3: Amount in Group Crcy | H3: English | I3: Deutsch | J3: 日本語 | K3: Portugues | L3: 中文
A4: FS Item | B4: FS Item | C4: J10 | D4: J1R | E4: J20 | F4: J2R
A5: 111100 | B5: =VLOOKUP(A5,Sheet2!A:F,1+'Balance 2023.12'!C$1,FALSE) -> Cash on hand | C5: 17278224 | D5: 17278224 | E5: 24046108 | F5: 24046108
A6: 111200 | B6: =VLOOKUP(A6,Sheet2!A:F,1+'Balance 2023.12'!C$1,FALSE) -> Short-term deposits and other cash equivalents | C6: 8057775.2 | D6: 8057775.2 | E6: 11214008 | F6: 11214008
A7: 121100 | B7: =VLOOKUP(A7,Sheet2!A:F,1+'Balance 2023.12'!C$1,FALSE) -> Trade receivables, Gross | C7: 27016242 | D7: 27026921 | E7: 37598510 | F7: 37613371
A8: 121190 | B8: =VLOOKUP(A8,Sheet2!A:F,1+'Balance 2023.12'!C$1,FALSE) -> Trade receivables, Allowance | C8: -931550.74 | D8: -931550.74 | E8: -1296439.4 | F8: -1296439.4
A9: 121200 | B9: =VLOOKUP(A9,Sheet2!A:F,1+'Balance 2023.12'!C$1,FALSE) -> Receivables on disposal of PPE, Current, Gross | C9: 8519.82 | D9: 8519.82 | E9: 11857.03 | F9: 11857.03
A10: 121300 | B10: =VLOOKUP(A10,Sheet2!A:F,1+'Balance 2023.12'!C$1,FALSE) -> Receivables / disp. Intang.assets, Current, Gross | C10: 5679.88 | D10: 5679.88 | E10: 7904.69 | F10: 7904.69
A11: 121400 | B11: =VLOOKUP(A11,Sheet2!A:F,1+'Balance 2023.12'!C$1,FALSE) -> Receivables / disp. invest. subsid, Current, Gross | C11: 1324.84 | D11: 1324.84 | E11: 1843.78 | F11: 1843.78
A12: 121500 | B12: =VLOOKUP(A12,Sheet2!A:F,1+'Balance 2023.12'!C$1,FALSE) -> Receivables / disp. Inv. oth entities, Current, GV | C12: 3974.51 | D12: 3974.51 | E12: 5531.33 | F12: 5531.33
A13: 121600 | B13: =VLOOKUP(A13,Sheet2!A:F,1+'Balance 2023.12'!C$1,FALSE) -> Receivables /disp. Inv. oth assets, Current, Gross | C13: 2839.94 | D13: 2839.94 | E13: 3952.35 | F13: 3952.35
A14: 121700 | B14: =VLOOKUP(A14,Sheet2!A:F,1+'Balance 2023.12'!C$1,FALSE) -> Dividends receivable | C14: 1500 | D14: 1500 | E14: 2087.55 | F14: 2087.55
A15: 121800 | B15: =VLOOKUP(A15,Sheet2!A:F,1+'Balance 2023.12'!C$1,FALSE) -> Other receivables, Current, Gross | C15: 678279.37 | D15: 678279.37 | E15: 943961.54 | F15: 943961.54
A16: 121900 | B16: =VLOOKUP(A16,Sheet2!A:F,1+'Balance 2023.12'!C$1,FALSE) -> Accrued interests on receivables | C16: 48278.95 | D16: 48278.95 | E16: 67189.82 | F16: 67189.82
... A163: 799000 | B163: =VLOOKUP(A163,Sheet2!A:F,1+'Balance 2023.12'!C$1,FALSE) -> Net income/loss | C163: 22090605 | D163: 22092426 | E163: 32497223 | F163: 32499901
A164: 13100D | B164: =VLOOKUP(A164,Sheet2!A:F,1+'Balance 2023.12'!C$1,FALSE) -> Clearing Account - Gross Margin B/S | C164: 0 | D164: 0 | E164: 0 | F164: 0
A165: 1721HC | B165: =VLOOKUP(A165,Sheet2!A:F,1+'Balance 2023.12'!C$1,FALSE) -> Elimination of investment, held cons unit | C165: -1612000 | D165: -1612000 | E165: -2370607.2 | F165: -2370607.2
A166: 1721OC | B166: =VLOOKUP(A166,Sheet2!A:F,1+'Balance 2023.12'!C$1,FALSE) -> Elimination of investment, owner cons unit | C166: 1612000 | D166: 1612000 | E166: 2370607.2 | F166: 2370607.2
A167: 21100D | B167: =VLOOKUP(A167,Sheet2!A:F,1+'Balance 2023.12'!C$1,FALSE) -> Clearing account - Receivables/payables, Current | C167: 0 | D167: 0 | E167: 0 | F167: 0
A168: 21110D | B168: =VLOOKUP(A168,Sheet2!A:F,1+'Balance 2023.12'!C$1,FALSE) -> Clearing account - Trade Rec/Pay, Current | C168: 0 | D168: 0 | E168: 0 | F168: 0
A169: 21170D | B169: =VLOOKUP(A169,Sheet2!A:F,1+'Balance 2023.12'!C$1,FALSE) -> Clearing - Dividends rec/pay, Current | C169: 0 | D169: 0 | E169: 0 | F169: 0
A170: 22100D | B170: =VLOOKUP(A170,Sheet2!A:F,1+'Balance 2023.12'!C$1,FALSE) -> Clearing account - Financial assets/liab, Current | C170: 0 | D170: 0 | E170: 0 | F170: 0
A171: 28100D | B171: =VLOOKUP(A171,Sheet2!A:F,1+'Balance 2023.12'!C$1,FALSE) -> Clearing account - Receiv./payables, Non-current | C171: 0 | D171: 0 | E171: 0 | F171: 0
A172: 41200D | B172: =VLOOKUP(A172,Sheet2!A:F,1+'Balance 2023.12'!C$1,FALSE) -> Clearing account - Gross margin | C172: 0 | D172: 0 | E172: 0 | F172: 0
A173: 58000D | B173: =VLOOKUP(A173,Sheet2!A:F,1+'Balance 2023.12'!C$1,FALSE) -> Clearing account - Other operating | C173: 0 | D173: 0 | E173: 0.01 | F173: 0.01
A174: 65400D | B174: =VLOOKUP(A174,Sheet2!A:F,1+'Balance 2023.12'!C$1,FALSE) -> Clearing account - financial result | C174: 0 | D174: 0 | E174: -0.01 | F174: -0.01

Sheet Balance Sheet 2023.12
A1: Language/ Sprache/ 言語/ Linguagem >>> | B1: English | C1: =MATCH(B1, H3:L3,0) -> 1
B3: Measures | C3: Sign-Adjusted Amount in Group Crcy | H3: English | I3: Deutsch | J3: 日本語 | K3: Portugues | L3: 中文
A4: FS Item | C4: J10 | D4: J1R | E4: J20 | F4: J2R
A5: Y1/BS/BS | B5: =VLOOKUP(A5,Sheet2!A:F,1+'Balance Sheet 2023.12'!C$1,FALSE) -> Balance Sheet | C5: 0 | D5: 0 | E5: 0 | F5: 0
A6: Y1/BS/TA0000 | B6: =VLOOKUP(A6,Sheet2!A:F,1+'Balance Sheet 2023.12'!C$1,FALSE) -> Assets | C6: 80471832 | D6: 80481211 | E6: 1.1199267e+08 | F6: 1.1200572e+08
A7: Y1/BS/TAC000 | B7: =VLOOKUP(A7,Sheet2!A:F,1+'Balance Sheet 2023.12'!C$1,FALSE) -> Current assets | C7: 58389764 | D7: 58400442 | E7: 81261046 | F7: 81275908
A8: Y1/BS/TAC100 | B8: =VLOOKUP(A8,Sheet2!A:F,1+'Balance Sheet 2023.12'!C$1,FALSE) -> Current assets oth.than incl.in disposal groups | C8: 58387764 | D8: 58398442 | E8: 81258263 | F8: 81273125
A9: Y1/BS/T11100 | B9: =VLOOKUP(A9,Sheet2!A:F,1+'Balance Sheet 2023.12'!C$1,FALSE) -> Cash and cash equivalents | C9: 25335999 | D9: 25335999 | E9: 35260116 | F9: 35260116
A10: 111100 | B10: =VLOOKUP(A10,Sheet2!A:F,1+'Balance Sheet 2023.12'!C$1,FALSE) -> Cash on hand | C10: 17278224 | D10: 17278224 | E10: 24046108 | F10: 24046108
A11: 111200 | B11: =VLOOKUP(A11,Sheet2!A:F,1+'Balance Sheet 2023.12'!C$1,FALSE) -> Short-term deposits and other cash equivalents | C11: 8057775.2 | D11: 8057775.2 | E11: 11214008 | F11: 11214008
A12: Y1/BS/T12100 | B12: =VLOOKUP(A12,Sheet2!A:F,1+'Balance Sheet 2023.12'!C$1,FALSE) -> Trade and other current receivables | C12: 26815209 | D12: 26825888 | E12: 37318732 | F12: 37333594
A13: 121100 | B13: =VLOOKUP(A13,Sheet2!A:F,1+'Balance Sheet 2023.12'!C$1,FALSE) -> Trade receivables, Gross | C13: 27016242 | D13: 27026921 | E13: 37598510 | F13: 37613371
A14: 121190 | B14: =VLOOKUP(A14,Sheet2!A:F,1+'Balance Sheet 2023.12'!C$1,FALSE) -> Trade receivables, Allowance | C14: -931550.74 | D14: -931550.74 | E14: -1296439.4 | F14: -1296439.4
A15: 121200 | B15: =VLOOKUP(A15,Sheet2!A:F,1+'Balance Sheet 2023.12'!C$1,FALSE) -> Receivables on disposal of PPE, Current, Gross | C15: 8519.82 | D15: 8519.82 | E15: 11857.03 | F15: 11857.03
A16: 121300 | B16: =VLOOKUP(A16,Sheet2!A:F,1+'Balance Sheet 2023.12'!C$1,FALSE) -> Receivables / disp. Intang.assets, Current, Gross | C16: 5679.88 | D16: 5679.88 | E16: 7904.69 | F16: 7904.69
A17: 121400 | B17: =VLOOKUP(A17,Sheet2!A:F,1+'Balance Sheet 2023.12'!C$1,FALSE) -> Receivables / disp. invest. subsid, Current, Gross | C17: 1324.84 | D17: 1324.84 | E17: 1843.78 | F17: 1843.78
A18: 121500 | B18: =VLOOKUP(A18,Sheet2!A:F,1+'Balance Sheet 2023.12'!C$1,FALSE) -> Receivables / disp. Inv. oth entities, Current, GV | C18: 3974.51 | D18: 3974.51 | E18: 5531.33 | F18: 5531.33
A19: 121600 | B19: =VLOOKUP(A19,Sheet2!A:F,1+'Balance Sheet 2023.12'!C$1,FALSE) -> Receivables /disp. Inv. oth assets, Current, Gross | C19: 2839.94 | D19: 2839.94 | E19: 3952.35 | F19: 3952.35
A20: 121700 | B20: =VLOOKUP(A20,Sheet2!A:F,1+'Balance Sheet 2023.12'!C$1,FALSE) -> Dividends receivable | C20: 1500 | D20: 1500 | E20: 2087.55 | F20: 2087.55
A21: 121800 | B21: =VLOOKUP(A21,Sheet2!A:F,1+'Balance Sheet 2023.12'!C$1,FALSE) -> Other receivables, Current, Gross | C21: 678279.37 | D21: 678279.37 | E21: 943961.54 | F21: 943961.54
A22: 121900 | B22: =VLOOKUP(A22,Sheet2!A:F,1+'Balance Sheet 2023.12'!C$1,FALSE) -> Accrued interests on receivables | C22: 48278.95 | D22: 48278.95 | E22: 67189.82 | F22: 67189.82
A23: 121990 | B23: =VLOOKUP(A23,Sheet2!A:F,1+'Balance Sheet 2023.12'!C$1,FALSE) -> Other receivables, Allow | C23: -19879.57 | D23: -19879.57 | E23: -27666.4 | F23: -27666.4
A24: Y1/BS/T12300 | B24: =VLOOKUP(A24,Sheet2!A:F,1+'Balance Sheet 2023.12'!C$1,FALSE) -> Other current assets | C24: 49494.5 | D24: 49494.5 | E24: 68881.51 | F24: 68881.51
A25: 123100 | B25: =VLOOKUP(A25,Sheet2!A:F,1+'Balance Sheet 2023.12'!C$1,FALSE) -> Prepaid expenses | C25: 49494.5 | D25: 49494.5 | E25: 68881.51 | F25: 68881.51
A26: Y1/BS/T13100 | B26: =VLOOKUP(A26,Sheet2!A:F,1+'Balance Sheet 2023.12'!C$1,FALSE) -> Inventories | C26: 6127657.6 | D26: 6127657.6 | E26: 8527862.1 | F26: 8527862.1
A27: 131100 | B27: =VLOOKUP(A27,Sheet2!A:F,1+'Balance Sheet 2023.12'!C$1,FALSE) -> Raw materials | C27: 2194399.5 | D27: 2194399.5 | E27: 3053946.2 | F27: 3053946.2
A28: 131200 | B28: =VLOOKUP(A28,Sheet2!A:F,1+'Balance Sheet 2023.12'!C$1,FALSE) -> Merchandise | C28: 2568881.8 | D28: 2568881.8 | E28: 3575113.2 | F28: 3575113.2
A29: 131300 | B29: =VLOOKUP(A29,Sheet2!A:F,1+'Balance Sheet 2023.12'!C$1,FALSE) -> Production supplies | C29: 2271.96 | D29: 2271.96 | E29: 3161.88 | F29: 3161.88
A30: 131400 | B30: =VLOOKUP(A30,Sheet2!A:F,1+'Balance Sheet 2023.12'!C$1,FALSE) -> Work in progress | C30: 674933.05 | D30: 674933.05 | E30: 939304.45 | F30: 939304.45
A31: 131500 | B31: =VLOOKUP(A31,Sheet2!A:F,1+'Balance Sheet 2023.12'!C$1,FALSE) -> Finished goods | C31: 685751.33 | D31: 685751.33 | E31: 954360.24 | F31: 954360.24
A32: 131600 | B32: =VLOOKUP(A32,Sheet2!A:F,1+'Balance Sheet 2023.12'!C$1,FALSE) -> Other inventories | C32: 1419.98 | D32: 1419.98 | E32: 1976.17 | F32: 1976.17
A33: 13100D | B33: =VLOOKUP(A33,Sheet2!A:F,1+'Balance Sheet 2023.12'!C$1,FALSE) -> Clearing Account - Gross Margin B/S | C33: 0 | D33: 0 | E33: 0 | F33: 0
A34: Y1/BS/T14100 | B34: =VLOOKUP(A34,Sheet2!A:F,1+'Balance Sheet 2023.12'!C$1,FALSE) -> Other current financial assets | C34: 59403.22 | D34: 59403.22 | E34: 82671.46 | F34: 82671.46
A35: 141100 | B35: =VLOOKUP(A35,Sheet2!A:F,1+'Balance Sheet 2023.12'!C$1,FALSE) -> Other financial assets at FVTOCI, Current | C35: 20515.85 | D35: 20515.85 | E35: 28551.91 | F35: 28551.91
A36: 141200 | B36: =VLOOKUP(A36,Sheet2!A:F,1+'Balance Sheet 2023.12'!C$1,FALSE) -> Derivatives, Current | C36: 10456 | D36: 10456 | E36: 14551.61 | F36: 14551.61
A37: 141300 | B37: =VLOOKUP(A37,Sheet2!A:F,1+'Balance Sheet 2023.12'!C$1,FALSE) -> Financial assets at FVPL, Current | C37: 5711.86 | D37: 5711.86 | E37: 7949.2 | F37: 7949.2
A38: 141400 | B38: =VLOOKUP(A38,Sheet2!A:F,1+'Balance Sheet 2023.12'!C$1,FALSE) -> Loans and cash advances, Current, Gross | C38: 31239.32 | D38: 31239.32 | E38: 43475.77 | F38: 43475.77
A39: 141490 | B39: =VLOOKUP(A39,Sheet2!A:F,1+'Balance Sheet 2023.12'!C$1,FALSE) -> Loans and cash advances, Current, Allowance | C39: -8519.81 | D39: -8519.81 | E39: -11857.03 | F39: -11857.03
A40: Y1/BS/TAC200 | B40: =VLOOKUP(A40,Sheet2!A:F,1+'Balance Sheet 2023.12'!C$1,FALSE) -> NC assets or disp. groups classified HFS/HDO | C40: 2000 | D40: 2000 | E40: 2783.4 | F40: 2783.4
A41: 151100 | B41: =VLOOKUP(A41,Sheet2!A:F,1+'Balance Sheet 2023.12'!C$1,FALSE) -> NC assets or disp. groups classified HFS | C41: 2000 | D41: 2000 | E41: 2783.4 | F41: 2783.4
...

Sheet P&L 2023.12
A1: Language/ Sprache/ 言語/ Linguagem >>> | B1: English | C1: =MATCH(B1, H3:L3,0) -> 1
B3: Measures | C3: Sign-Adjusted Amount in Group Crcy | H3: English | I3: Deutsch | J3: 日本語 | K3: Portugues | L3: 中文
A4: FS Item | B4: FS Item | C4: J10 | D4: J1R | E4: J20 | F4: J2R
A5: Y1/PL/PL | B5: =VLOOKUP(A5,Sheet2!A:F,1+'P&L 2023.12'!C$1,FALSE) -> Profit & Loss Statement | C5: 0 | D5: 0 | E5: 0 | F5: 0
A6: 799000 | B6: =VLOOKUP(A6,Sheet2!A:F,1+'P&L 2023.12'!C$1,FALSE) -> Net income/loss | C6: 22090605 | D6: 22092426 | E6: 32497223 | F6: 32499901
A7: Y1/PL/TNI000 | B7: =VLOOKUP(A7,Sheet2!A:F,1+'P&L 2023.12'!C$1,FALSE) -> NET INCOME / LOSS | C7: 22090605 | D7: 22092426 | E7: 32497223 | F7: 32499901
A8: Y1/PL/TBT000 | B8: =VLOOKUP(A8,Sheet2!A:F,1+'P&L 2023.12'!C$1,FALSE) -> Profit (loss) before tax | C8: 45933363 | D8: 45935444 | E8: 67562879 | F8: 67565940
A9: Y1/PL/TBFT00 | B9: =VLOOKUP(A9,Sheet2!A:F,1+'P&L 2023.12'!C$1,FALSE) -> Profit Before Financing and Income Taxes | C9: 46968982 | D9: 46968462 | E9: 69085860 | F9: 69085095
A10: Y1/PL/TOI000 | B10: =VLOOKUP(A10,Sheet2!A:F,1+'P&L 2023.12'!C$1,FALSE) -> Operating income / loss | C10: 26634131 | D10: 26634131 | E10: 39181432 | F10: 39181432
A11: Y1/PL/T41000 | B11: =VLOOKUP(A11,Sheet2!A:F,1+'P&L 2023.12'!C$1,FALSE) -> Gross margin | C11: 1.549024e+08 | D11: 1.549024e+08 | E11: 2.2781272e+08 | F11: 2.2781272e+08
A12: Y1/PL/T41100 | B12: =VLOOKUP(A12,Sheet2!A:F,1+'P&L 2023.12'!C$1,FALSE) -> Revenue | C12: 2.4917317e+08 | D12: 2.4917317e+08 | E12: 3.6643401e+08 | F12: 3.6643401e+08
A13: 411100 | B13: =VLOOKUP(A13,Sheet2!A:F,1+'P&L 2023.12'!C$1,FALSE) -> Sale of goods | C13: 2.4917317e+08 | D13: 2.4917317e+08 | E13: 3.6643401e+08 | F13: 3.6643401e+08
A14: Y1/PL/T41200 | B14: =VLOOKUP(A14,Sheet2!A:F,1+'P&L 2023.12'!C$1,FALSE) -> Changes in Inventory / COS | C14: -94270769 | D14: -94270769 | E14: -1.3862129e+08 | F14: -1.3862129e+08
A15: 412100 | B15: =VLOOKUP(A15,Sheet2!A:F,1+'P&L 2023.12'!C$1,FALSE) -> Changes in Inventory | C15: -10949723 | D15: -10949723 | E15: -16089373 | F15: -16089373
A16: 412200 | B16: =VLOOKUP(A16,Sheet2!A:F,1+'P&L 2023.12'!C$1,FALSE) -> Cost of purchased services and materials | C16: -83321046 | D16: -83321046 | E16: -1.2253191e+08 | F16: -1.2253191e+08
A17: 41200D | B17: =VLOOKUP(A17,Sheet2!A:F,1+'P&L 2023.12'!C$1,FALSE) -> Clearing account - Gross margin | C17: 0 | D17: 0 | E17: 0 | F17: 0
A18: Y1/PL/T57000 | B18: =VLOOKUP(A18,Sheet2!A:F,1+'P&L 2023.12'!C$1,FALSE) -> Depreciation | C18: -30000 | D18: -30000 | E18: -44118 | F18: -44118
A19: 571000 | B19: =VLOOKUP(A19,Sheet2!A:F,1+'P&L 2023.12'!C$1,FALSE) -> Amort./depr./ impair. on fixed assets | C19: -30000 | D19: -30000 | E19: -44118 | F19: -44118
A20: Y1/PL/T51000 | B20: =VLOOKUP(A20,Sheet2!A:F,1+'P&L 2023.12'!C$1,FALSE) -> Other operating income | C20: 1953265.9 | D20: 1953265.9 | E20: 2872472.4 | F20: 2872472.4
A21: 511000 | B21: =VLOOKUP(A21,Sheet2!A:F,1+'P&L 2023.12'!C$1,FALSE) -> Gains on the disposal of PPE | C21: 1744709.9 | D21: 1744709.9 | E21: 2565770 | F21: 2565770
A22: 511200 | B22: =VLOOKUP(A22,Sheet2!A:F,1+'P&L 2023.12'!C$1,FALSE) -> Gains on the disposal of intangible assets | C22: 13654.06 | D22: 13654.06 | E22: 20079.65 | F22: 20079.65
A23: 511300 | B23: =VLOOKUP(A23,Sheet2!A:F,1+'P&L 2023.12'!C$1,FALSE) -> Gains on the disposal of other assets | C23: 10939.96 | D23: 10939.96 | E23: 16088.3 | F23: 16088.3
A24: 515000 | B24: =VLOOKUP(A24,Sheet2!A:F,1+'P&L 2023.12'!C$1,FALSE) -> Other operating income | C24: 183961.98 | D24: 183961.98 | E24: 270534.46 | F24: 270534.46
A25: Y1/PL/T58000 | B25: =VLOOKUP(A25,Sheet2!A:F,1+'P&L 2023.12'!C$1,FALSE) -> Other operating expenses | C25: -1.3019154e+08 | D25: -1.3019154e+08 | E25: -1.9145964e+08 | F25: -1.9145964e+08
A26: 584000 | B26: =VLOOKUP(A26,Sheet2!A:F,1+'P&L 2023.12'!C$1,FALSE) -> Accruals | C26: -134732.64 | D26: -134732.64 | E26: -198137.76 | F26: -198137.76
A27: 585000 | B27: =VLOOKUP(A27,Sheet2!A:F,1+'P&L 2023.12'!C$1,FALSE) -> Other operating expenses | C27: -1.300568e+08 | D27: -1.300568e+08 | E27: -1.9126151e+08 | F27: -1.9126151e+08
A28: 58000D | B28: =VLOOKUP(A28,Sheet2!A:F,1+'P&L 2023.12'!C$1,FALSE) -> Clearing account - Other operating | C28: 0 | D28: 0 | E28: -0.01 | F28: -0.01
A29: 651000 | B29: =VLOOKUP(A29,Sheet2!A:F,1+'P&L 2023.12'!C$1,FALSE) -> Allowances (reversals) for provisions on shares | C29: 0 | D29: 0 | E29: 0 | F29: 0
A30: Y1/PL/TIIL00 | B30: =VLOOKUP(A30,Sheet2!A:F,1+'P&L 2023.12'!C$1,FALSE) -> Investing Income / Loss | C30: 20334851 | D30: 20334331 | E30: 29904428 | F30: 29903663
A31: 511100 | B31: =VLOOKUP(A31,Sheet2!A:F,1+'P&L 2023.12'!C$1,FALSE) -> Gains on the disposal of investment property | C31: 19220955 | D31: 19220955 | E31: 28266332 | F31: 28266332
A32: 601000 | B32: =VLOOKUP(A32,Sheet2!A:F,1+'P&L 2023.12'!C$1,FALSE) -> Interest income | C32: 898112.87 | D32: 898112.87 | E32: 1320764.6 | F32: 1320764.6
A33: 603000 | B33: =VLOOKUP(A33,Sheet2!A:F,1+'P&L 2023.12'!C$1,FALSE) -> Dividends | C33: 185713.42 | D33: 185713.42 | E33: 273110.59 | F33: 273110.59
A34: 711000 | B34: =VLOOKUP(A34,Sheet2!A:F,1+'P&L 2023.12'!C$1,FALSE) -> Share of profit - associates / JV at equity method | C34: 30070.04 | D34: 29550.04 | E34: 44221 | F34: 43456.29
A35: Y1/PL/TFIL00 | B35: =VLOOKUP(A35,Sheet2!A:F,1+'P&L 2023.12'!C$1,FALSE) -> Financing Income / Loss | C35: -1035618.6 | D35: -1033017.6 | E35: -1522980.4 | F35: -1519155.4
A36: 602000 | B36: =VLOOKUP(A36,Sheet2!A:F,1+'P&L 2023.12'!C$1,FALSE) -> Financial fair value gains or losses | C36: 19888.12 | D36: 19888.12 | E36: 29247.47 | F36: 29247.47
A37: 604000 | B37: =VLOOKUP(A37,Sheet2!A:F,1+'P&L 2023.12'!C$1,FALSE) -> Other financial income | C37: 564307.44 | D37: 564307.44 | E37: 829870.37 | F37: 829870.37
A38: 652000 | B38: =VLOOKUP(A38,Sheet2!A:F,1+'P&L 2023.12'!C$1,FALSE) -> Interest expenses | C38: -62705.42 | D38: -62705.42 | E38: -92214.57 | F38: -92214.57
A39: 653000 | B39: =VLOOKUP(A39,Sheet2!A:F,1+'P&L 2023.12'!C$1,FALSE) -> Other financial expenses | C39: -1557108.7 | D39: -1554507.7 | E39: -2289883.7 | F39: -2286058.7
A40: 65400D | B40: =VLOOKUP(A40,Sheet2!A:F,1+'P&L 2023.12'!C$1,FALSE) -> Clearing account - financial result | C40: 0 | D40: 0 | E40: 0.01 | F40: 0.01
A41: Y1/PL/T72000 | B41: =VLOOKUP(A41,Sheet2!A:F,1+'P&L 2023.12'!C$1,FALSE) -> Tax | C41: -11049256 | D41: -11049256 | E41: -16249033 | F41: -16249033
...

Sheet Sheet2
B1: I_TXTMI_EN | C1: I_TXTMI_DE | D1: I_TXTMI_JA | E1: I_TXTMI_PT | F1: I_TXTMI_ZH
A2: 0 | B2: Control | C2: Steuern | D2: コントロール | E2: Ao controle
A3: 1 | B3: Control 1 | C3: Steuern 1 | D3: コントロール 1 | E3: Ao controle 1
A4: 2 | B4: Control 2 | C4: Steuern 2 | D4: コントロール 2 | E4: Ao controle 2
A5: 3 | B5: Control 3 | C5: Steuern 3 | D5: コントロール 3 | E5: Ao controle 3
A6: 111100 | B6: Cash on hand | C6: Kassenbestand | D6: 手許現金 | E6: Ativo em caixa | F6: 库存现金
A7: 111200 | B7: Short-term deposits and other cash equivalents | C7: Kurzfr. Einlagen und andere Zahlungsmitteläquiv. | D7: 短期預金およびその他現金同等物 | E7: Depósitos a curto prazo e outros recursos líquidos | F7: 短期存款及其他现金等价物
A8: 121100 | B8: Trade receivables, Gross | C8: Forderungen aus Lieferungen und Leistungen, brutto | D8: 売上債権、総額 | E8: Créditos comerciais, bruto | F8: 贸易应收账款，总额
A9: 121190 | B9: Trade receivables, Allowance | C9: Forderungen aus Lief. und Leist., Wertberichtigung | D9: 売上債権、引当金 | E9: Créditos comerciais, ajuste de valor | F9: 贸易应收账款，补贴
A10: 121200 | B10: Receivables on disposal of PPE, Current, Gross | C10: Ford. aus Abgang von Sachanlagen, kurzfr., brutto | D10: PPE 処分の流動債権、総額 | E10: Créds.em alienação bem mat., curto prazo, bruto | F10: 物业、工厂与设备处置流动应收账款总额
A11: 121300 | B11: Receivables / disp. Intang.assets, Current, Gross | C11: Ford. aus Abgang imm. VermGgnst., kurzfr., brutto | D11: 無形資産の流動債権/処分、総額 | E11: Créds./alienação bens intangs., curto prz., bruto | F11: 无形资产处置应收账款的流动总额
A12: 121400 | B12: Receivables / disp. invest. subsid, Current, Gross | C12: Ford. aus Abgang Beteil. Tochter, kurzfr., brutto | D12: 子会社への投資の流動債権/処分、総額 | E12: Créds./alienação subsid.invest., curto prz., bruto | F12: 子公司投资处置应收账款的流动总额
A13: 121500 | B13: Receivables / disp. Inv. oth entities, Current, GV | C13: Ford. aus Abgang Beteil. an so. Einh., kurzfr., BW | D13: その他エンティティへの投資の流動債権/処分、GV | E13: Créds./alien.inv.outs.entds., curto prazo, bruto | F13: 其他实体投资处置应收账款的流动总价值
A14: 121600 | B14: Receivables /disp. Inv. oth assets, Current, Gross | C14: Ford. aus Abgang Btlg so. VermW., kurzfr., brutto | D14: その他資産への投資の流動債権/処分、総額 | E14: Créds./alien.inv.outros imobs., curto prazo, bruto | F14: 其他资产投资处置应收账款的流动总额
A15: 121700 | B15: Dividends receivable | C15: Dividendenforderung | D15: 未収配当金 | E15: Dividendos a receber | F15: 应收股利
A16: 121800 | B16: Other receivables, Current, Gross | C16: Sonstige Forderungen, kurzfristig, brutto | D16: その他流動債権、総額 | E16: Outros créditos, curto prazo, bruto | F16: 其他流动应收账款总额
A17: 121900 | B17: Accrued interests on receivables | C17: Aufgelaufene Zinsen auf Forderungen | D17: 債権の見越利息 | E17: Juros acumulados sobre créditos | F17: 应收账款的应计利息
... A217: 799999 | B217: Secondary cost element | C217: Sekundärkostenart | D217: 二次原価要素 | E217: Classe de custo secundário | F217: 次要成本要素
A218: 13100D | B218: Clearing Account - Gross Margin B/S | C218: Verrekeningsrekening - balans brutomarge | D218: 消込勘定 - 粗利益 B/S | E218: Conta compensação - margem bruta balanço | F218: 清账科目 - 总利润率资产负债表
A219: 14100D | B219: Clearing account - Financial assets, Current | C219: Verrechnungskonto - Fin. Vermögenswerte, kurzfr. | D219: 消込勘定 - 流動金融資産 | E219: Cta.compensação - imobilizados financeiros, CP | F219: 清账科目 - 流动金融资产
A220: 16100D | B220: Clearing account - Property, plant and equipment | C220: Verrechnungskonto - Sachanlagen | D220: 消込勘定 - 有形固定資産 | E220: Conta de compensação - bem material | F220: 清账科目 - 物业、工厂和设备
A221: 16200D | B221: Clearing account - Investment property | C221: Verrechnungskonto - Als Finanzinvest. geh. Immob. | D221: 消込勘定 - 投資不動産 | E221: Conta compensação - propriedade investimento | F221: 清账科目 - 投资财产
A222: 16300D | B222: Clearing account - Bargain purchase | C222: Verrechnungskonto - Erwerb unter dem Marktwert | D222: 消込勘定 - バーゲンパーチェス | E222: Conta compensação - compra favorável | F222: 清账科目 - 折价购买
A223: 16400D | B223: Clearing account - Intangible assets | C223: Verrechnungskonto - Immat. Vermögensgegenstände | D223: 消込勘定 - 無形資産 | E223: Conta de compensação - imobilizados intangíveis | F223: 清账科目 - 无形资产
A224: 17210D | B224: Clearing account - Investments in subs, JV, assoc. | C224: VerrechKto - Beteil. an Tochterges., JV, ass. Unt. | D224: 消込勘定 - 子会社、JV および関連会社への投資 | E224: Conta compensação - invs.subs., JV, empr.assocs. | F224: 清账科目 - 子公司、合资企业、附属公司投资
A225: 1721HC | B225: Elimination of investment, held cons unit | C225: Beteiligungseliminierung, gehaltene KonsEinheit | D225: 投資の消去、被保有連結単位 | E225: Eliminação investimento, unid.consolidação prev. | F225: 投资抵销，持有消耗单元
A226: 1721OC | B226: Elimination of investment, owner cons unit | C226: Beteiligungseliminierung, Eigentümer KonsEinheit | D226: 投資の消去、所有者連結単位 | E226: Eliminação investimento, propr.unid.consolidação | F226: 投资抵销，所有者消耗单元
A227: 17220D | B227: Clearing account - Financial assets, Non-current | C227: Verrechnungskonto - Fin. Vermögenswerte, langfr. | D227: 消込勘定 - 非流動金融資産 | E227: Conta compensação - imobs.financeiros, longo prazo | F227: 清账科目 - 非流动金融资产
A228: 19900D | B228: Balancing account - B/S | C228: Ausgleichskonto - Bilanz | D228: 残高調整勘定 - B/S | E228: Conta de compensação - balanço | F228: 结算科目 - 资产负债表
A229: 21100D | B229: Clearing account - Receivables/payables, Current | C229: Verrechnungskonto - Ford./Verbindl., kurzfristig | D229: 消込勘定 - 流動債権/債務 | E229: Conta compensação - créds./obrigações, curto prazo | F229: 清账科目 - 流动应收账款/应付账款
... A246: AA | B246: Group share | C246: Konzernanteil | D246: グループシェア | E246: Compartilhamento de grupo | F246: Group share
A247: AAA | B247: Correction | C247: Korrektur | D247: 補正 | E247: Correção
A248: B | B248: Total liabilities | C248: Gesamtverbindlichkeiten | D248: 総負債 | E248: Resposabilidades totais | F248: 总负债
A249: BBB | B249: Cloud Consolidation | C249: Cloud-Konsolidierung | D249: クラウドの統合 | E249: Consolidação de nuvem
A250: BS | B250: Balance Sheet | C250: Bilanz | D250: 貸借対照表 | E250: Balanço | F250: 资产负债表
A251: C | B251: Total equity | C251: Gesamtkapital | D251: 総資本 | E251: Patrimônio total | F251: 总资本
A252: D | B252: Net income | C252: Nettoeinkommen | D252: 当期純利益 | E252: Resultado líquido | F252: 净收入
A253: E | B253: Amount in Group Crcy | C253: Bedrag concernvaluta | D253: グループ通貨額 | E253: Montante MGE | F253: 集团公司记帐货币
A254: F | B254: Sign-Adjusted Amount in Group Crcy | C254: Betrag mit angepasstem Vorzeichen in KW | D254: 符号調整済金額 (連結通貨) | E254: Montante c/sinal ajustado em MGC | F254: 以集团货币计的符号已调整金额
A255: Financial Statement Item | B255: Medium Text for FS Items | C255: Medium Text for FS Items | D255: Medium Text for FS Items | E255: Medium Text for FS Items | F255: Medium Text for FS Items
...
